Workbook

Sheet Project Brief
A1: FINAL PROJECT — Vantree Retail Group: 1-Year Sales Analysis
A2: This is your Month 1-2 capstone. Every skill from Weeks 1 through 7 is required somewhere in this project. No new tools this week — this week is about combining everything correctly.
A4: THE SCENARIO
A5: Vantree Retail Group's board meets in 5 days for the annual review.
A6: The raw sales export you were given covers 12 months and has NOT been cleaned.
A7: It has the same problems Orbitex had in Week 2, PLUS the text formatting
A8: problems from Week 7 — combined fields, inconsistent casing, duplicate entries.
A9: Your job: clean it, validate it, enrich it with lookups, aggregate it, and
A10: present a final dashboard with a written executive summary.
A12: THE FIVE PHASES — EVERY SKILL FROM MONTH 1-2 MAPPED TO A STEP
A13: Phase | B13: Skill Required | C13: What You Do | D13: Sheet To Use | E13: Week It's From
A14: Phase 1 | B14: Text Functions + Duplicates | C14: Clean Rep Name, Region, and Product columns. Remove duplicate orders. | D14: Raw Sales Data | E14: Week 7
A15: Phase 2 | B15: IF / AND / OR + Data Validation | C15: Flag negative quantities, impossible dates, and orders needing review. | D15: Raw Sales Data (new columns) | E15: Week 1-2
A16: Phase 3 | B16: VLOOKUP / INDEX MATCH | C16: Pull Unit Price and Department from Product Master and Employee Master. | D16: Raw Sales Data (new columns) | E16: Week 3
A17: Phase 4 | B17: SUMIFS / COUNTIFS | C17: Build the KPI Summary Row — total revenue, orders per rep, category totals. | D17: Executive Dashboard | E17: Week 5
A18: Phase 5 | B18: Pivot Tables + Charts + KPIs | C18: Build the final dashboard — Region, Category, Monthly Trend, Rep Ranking. | D18: Executive Dashboard | E18: Week 4 & 6
A20: FINAL DELIVERABLE — EXECUTIVE SUMMARY
A21: After the dashboard is built, write a 5-7 sentence executive summary on the Executive Dashboard sheet: what changed year over year, which region/category needs attention, and one clear recommendation. No AI drafting this part — this is the one piece that must be entirely yours.

Sheet Sheet1
A3: Row Labels | B3: Sum of Revenue | C3: Row Labels | D3: Sum of Revenue | E3: Row Labels | F3: Sum of Revenue
A4: January | B4: 5310 | C4: Sports | D4: 5787 | E4: Amanda Thomas | F4: 2220
A5: February | B5: 6263 | C5: Home Appliances | D5: 12268 | E5: Chris Anderson | F5: 1551
A6: March | B6: 3367 | C6: Electronics | D6: 25045 | E6: David Lee | F6: 6267
A7: April | B7: 7296 | C7: Clothing | D7: 7955 | E7: Emily Davis | F7: 4920
A8: May | B8: 1822 | C8: Beauty | D8: 9344 | E8: James Wilson | F8: 3657
A9: June | B9: 7242 | C9: Grand Total | D9: 60399 | E9: Jennifer Taylor | F9: 8979
A10: July | B10: 2487 | E10: Lisa Martinez | F10: 7504
A11: August | B11: 7334 | C11: Row Labels | D11: Sum of Revenue | E11: Mike Johnson | F11: 10078
A12: September | B12: 3087 | C12: Electronics | D12: 25045 | E12: Robert Brown | F12: 1189
A13: October | B13: 5884 | C13: Home Appliances | D13: 12268 | E13: Sarah Connor | F13: 14034
A14: November | B14: 4028 | C14: Beauty | D14: 9344 | E14: Grand Total | F14: 60399
A15: December | B15: 6279 | C15: Clothing | D15: 7955
A16: Grand Total | B16: 60399 | C16: Sports | D16: 5787
A18: Row Labels | B18: Sum of Revenue
A19: Amanda Thomas | B19: 2220
A20: Chris Anderson | B20: 1551
A21: David Lee | B21: 6267
A22: Emily Davis | B22: 4920
A23: James Wilson | B23: 3657
A24: Jennifer Taylor | B24: 8979
A25: Lisa Martinez | B25: 7504
A26: Mike Johnson | B26: 10078 | E26: Top Bottom Sales Rap performance
A27: Robert Brown | B27: 1189 | F27: Sales Rep | G27: Revenue | J27: Row Labels | K27: Count of Return Status
A28: Sarah Connor | B28: 14034 | F28: Sarah Connor | G28: 14034 | J28: Clothing | K28: 16
F29: Mike Johnson | G29: 10078 | J29: Beauty | K29: 16
F30: Jennifer Taylor | G30: 8979 | J30: Sports | K30: 16
C31: Amanda Thomas | D31: 2220 | F31: Amanda Thomas | G31: 2220 | J31: Home Appliances | K31: 16
C32: Chris Anderson | D32: 1551 | F32: Chris Anderson | G32: 1551 | J32: Electronics | K32: 32
C33: Robert Brown | D33: 1189 | F33: Robert Brown | G33: 1189 | J33: Grand Total | K33: 96

Sheet Raw Sales Data
A1: VANTREE RETAIL GROUP — 1-Year Raw Sales Export (Uncleaned)
A2: Same category of problems as Orbitex (Week 2) plus text formatting issues (Week 7). This is the messiest dataset in your journey so far — on purpose.
A3: Order ID | B3: Order Date | C3: Month | D3: Rep ID | E3: Rep Name | F3: Region | G3: Category | H3: Product Code | I3: Quantity | J3: Employee ID Ref | K3: Unit Price | L3: Delivery Date | M3: Revenue | N3: Payment Method | O3: Return Status
A4: VT-0001 | B4: 2025-01-04 | C4: January | D4: E002 | E4: Sarah Connor | F4: North | G4: Electronics | H4: EL-2205 | I4: 2 | J4: E002 | K4: {=_xlfn.IFS(H4="EL-2201",999,'Raw Sales Data'!H4="EL-2205",1299,'Raw Sales Data'!H4="EL-2210",1099,'Raw Sales Data'!H4="CL-1102",89,'Raw Sales Data'!H4="CL-1108",79,'Raw Sales Data'!H4="CL-1120",95,'Raw Sales Data'!H4="HA-3301",549,'Raw Sales Data'!H4="HA-3305",399,'Raw Sales Data'!H4="HA-3308",129,'Raw Sales Data'!H4="BE-4401",42,'Raw Sales Data'!H4="BE-4402",125,'Raw Sales Data'!H4="BE-4408",58,'Raw Sales Data'!H4="SP-5501",1495,'Raw Sales Data'!H4="SP-5505",299,'Raw Sales Data'!H4="SP-5510",249)} -> 1299 | L4: 2025-01-08 | M4: =K4*I4 -> 2598 | N4: PayPal | O4: No
A5: VT-0002 | B5: 2025-01-07 | C5: January | D5: E003 | E5: Mike Johnson | F5: North | G5: Electronics | H5: EL-2210 | I5: 1 | J5: E003 | K5: {=_xlfn.IFS(H5="EL-2201",999,'Raw Sales Data'!H5="EL-2205",1299,'Raw Sales Data'!H5="EL-2210",1099,'Raw Sales Data'!H5="CL-1102",89,'Raw Sales Data'!H5="CL-1108",79,'Raw Sales Data'!H5="CL-1120",95,'Raw Sales Data'!H5="HA-3301",549,'Raw Sales Data'!H5="HA-3305",399,'Raw Sales Data'!H5="HA-3308",129,'Raw Sales Data'!H5="BE-4401",42,'Raw Sales Data'!H5="BE-4402",125,'Raw Sales Data'!H5="BE-4408",58,'Raw Sales Data'!H5="SP-5501",1495,'Raw Sales Data'!H5="SP-5505",299,'Raw Sales Data'!H5="SP-5510",249)} -> 1099 | L5: 2025-01-12 | M5: =K5*I5 -> 1099 | N5: Debit Card | O5: No
A6: VT-0003 | B6: 2025-01-10 | C6: January | D6: E004 | E6: Emily Davis | F6: North | G6: Electronics | H6: CL-1102 | I6: 3 | J6: E004 | K6: {=_xlfn.IFS(H6="EL-2201",999,'Raw Sales Data'!H6="EL-2205",1299,'Raw Sales Data'!H6="EL-2210",1099,'Raw Sales Data'!H6="CL-1102",89,'Raw Sales Data'!H6="CL-1108",79,'Raw Sales Data'!H6="CL-1120",95,'Raw Sales Data'!H6="HA-3301",549,'Raw Sales Data'!H6="HA-3305",399,'Raw Sales Data'!H6="HA-3308",129,'Raw Sales Data'!H6="BE-4401",42,'Raw Sales Data'!H6="BE-4402",125,'Raw Sales Data'!H6="BE-4408",58,'Raw Sales Data'!H6="SP-5501",1495,'Raw Sales Data'!H6="SP-5505",299,'Raw Sales Data'!H6="SP-5510",249)} -> 89 | L6: 2025-01-13 | M6: =K6*I6 -> 267 | N6: Credit Card | O6: No
A7: VT-0004 | B7: 2025-01-13 | C7: January | D7: E005 | E7: Robert Brown | F7: South | G7: Clothing | H7: CL-1108 | I7: 1 | J7: E005 | K7: {=_xlfn.IFS(H7="EL-2201",999,'Raw Sales Data'!H7="EL-2205",1299,'Raw Sales Data'!H7="EL-2210",1099,'Raw Sales Data'!H7="CL-1102",89,'Raw Sales Data'!H7="CL-1108",79,'Raw Sales Data'!H7="CL-1120",95,'Raw Sales Data'!H7="HA-3301",549,'Raw Sales Data'!H7="HA-3305",399,'Raw Sales Data'!H7="HA-3308",129,'Raw Sales Data'!H7="BE-4401",42,'Raw Sales Data'!H7="BE-4402",125,'Raw Sales Data'!H7="BE-4408",58,'Raw Sales Data'!H7="SP-5501",1495,'Raw Sales Data'!H7="SP-5505",299,'Raw Sales Data'!H7="SP-5510",249)} -> 79 | L7: 2025-01-10 | M7: =K7*I7 -> 79 | N7: PayPal | O7: No
A8: VT-0005 | B8: 2025-01-16 | C8: January | D8: E006 | E8: Lisa Martinez | F8: South | G8: Clothing | H8: CL-1120 | I8: 2 | J8: E006 | K8: {=_xlfn.IFS(H8="EL-2201",999,'Raw Sales Data'!H8="EL-2205",1299,'Raw Sales Data'!H8="EL-2210",1099,'Raw Sales Data'!H8="CL-1102",89,'Raw Sales Data'!H8="CL-1108",79,'Raw Sales Data'!H8="CL-1120",95,'Raw Sales Data'!H8="HA-3301",549,'Raw Sales Data'!H8="HA-3305",399,'Raw Sales Data'!H8="HA-3308",129,'Raw Sales Data'!H8="BE-4401",42,'Raw Sales Data'!H8="BE-4402",125,'Raw Sales Data'!H8="BE-4408",58,'Raw Sales Data'!H8="SP-5501",1495,'Raw Sales Data'!H8="SP-5505",299,'Raw Sales Data'!H8="SP-5510",249)} -> 95 | L8: 2025-01-20 | M8: =K8*I8 -> 190 | N8: Debit Card | O8: No
A9: VT-0006 | B9: 2025-01-19 | C9: January | D9: E007 | E9: David Lee | F9: South | G9: Home Appliances | H9: HA-3301 | I9: 1 | J9: E007 | K9: {=_xlfn.IFS(H9="EL-2201",999,'Raw Sales Data'!H9="EL-2205",1299,'Raw Sales Data'!H9="EL-2210",1099,'Raw Sales Data'!H9="CL-1102",89,'Raw Sales Data'!H9="CL-1108",79,'Raw Sales Data'!H9="CL-1120",95,'Raw Sales Data'!H9="HA-3301",549,'Raw Sales Data'!H9="HA-3305",399,'Raw Sales Data'!H9="HA-3308",129,'Raw Sales Data'!H9="BE-4401",42,'Raw Sales Data'!H9="BE-4402",125,'Raw Sales Data'!H9="BE-4408",58,'Raw Sales Data'!H9="SP-5501",1495,'Raw Sales Data'!H9="SP-5505",299,'Raw Sales Data'!H9="SP-5510",249)} -> 549 | L9: 2025-01-22 | M9: =K9*I9 -> 549 | N9: Credit Card | O9: No
A10: VT-0007 | B10: 2025-01-22 | C10: January | D10: E008 | E10: Jennifer Taylor | F10: East | G10: Home Appliances | H10: HA-3305 | I10: 1 | J10: E008 | K10: {=_xlfn.IFS(H10="EL-2201",999,'Raw Sales Data'!H10="EL-2205",1299,'Raw Sales Data'!H10="EL-2210",1099,'Raw Sales Data'!H10="CL-1102",89,'Raw Sales Data'!H10="CL-1108",79,'Raw Sales Data'!H10="CL-1120",95,'Raw Sales Data'!H10="HA-3301",549,'Raw Sales Data'!H10="HA-3305",399,'Raw Sales Data'!H10="HA-3308",129,'Raw Sales Data'!H10="BE-4401",42,'Raw Sales Data'!H10="BE-4402",125,'Raw Sales Data'!H10="BE-4408",58,'Raw Sales Data'!H10="SP-5501",1495,'Raw Sales Data'!H10="SP-5505",299,'Raw Sales Data'!H10="SP-5510",249)} -> 399 | L10: 2025-01-27 | M10: =K10*I10 -> 399 | N10: PayPal | O10: No
A11: VT-0008 | B11: 2025-01-25 | C11: January | D11: E009 | E11: Chris Anderson | F11: East | G11: Beauty | H11: HA-3308 | I11: 1 | J11: E009 | K11: {=_xlfn.IFS(H11="EL-2201",999,'Raw Sales Data'!H11="EL-2205",1299,'Raw Sales Data'!H11="EL-2210",1099,'Raw Sales Data'!H11="CL-1102",89,'Raw Sales Data'!H11="CL-1108",79,'Raw Sales Data'!H11="CL-1120",95,'Raw Sales Data'!H11="HA-3301",549,'Raw Sales Data'!H11="HA-3305",399,'Raw Sales Data'!H11="HA-3308",129,'Raw Sales Data'!H11="BE-4401",42,'Raw Sales Data'!H11="BE-4402",125,'Raw Sales Data'!H11="BE-4408",58,'Raw Sales Data'!H11="SP-5501",1495,'Raw Sales Data'!H11="SP-5505",299,'Raw Sales Data'!H11="SP-5510",249)} -> 129 | L11: 2025-01-28 | M11: =K11*I11 -> 129 | N11: Debit Card | O11: No
A12: VT-0009 | B12: 2025-02-04 | C12: February | D12: E010 | E12: Amanda Thomas | F12: East | G12: Beauty | H12: BE-4401 | I12: 2 | J12: E010 | K12: {=_xlfn.IFS(H12="EL-2201",999,'Raw Sales Data'!H12="EL-2205",1299,'Raw Sales Data'!H12="EL-2210",1099,'Raw Sales Data'!H12="CL-1102",89,'Raw Sales Data'!H12="CL-1108",79,'Raw Sales Data'!H12="CL-1120",95,'Raw Sales Data'!H12="HA-3301",549,'Raw Sales Data'!H12="HA-3305",399,'Raw Sales Data'!H12="HA-3308",129,'Raw Sales Data'!H12="BE-4401",42,'Raw Sales Data'!H12="BE-4402",125,'Raw Sales Data'!H12="BE-4408",58,'Raw Sales Data'!H12="SP-5501",1495,'Raw Sales Data'!H12="SP-5505",299,'Raw Sales Data'!H12="SP-5510",249)} -> 42 | L12: 2025-02-07 | M12: =K12*I12 -> 84 | N12: Credit Card | O12: No
A13: VT-0010 | B13: 2025-02-07 | C13: February | D13: E001 | E13: James Wilson | F13: West | G13: Sports | H13: BE-4402 | I13: 1 | J13: E001 | K13: {=_xlfn.IFS(H13="EL-2201",999,'Raw Sales Data'!H13="EL-2205",1299,'Raw Sales Data'!H13="EL-2210",1099,'Raw Sales Data'!H13="CL-1102",89,'Raw Sales Data'!H13="CL-1108",79,'Raw Sales Data'!H13="CL-1120",95,'Raw Sales Data'!H13="HA-3301",549,'Raw Sales Data'!H13="HA-3305",399,'Raw Sales Data'!H13="HA-3308",129,'Raw Sales Data'!H13="BE-4401",42,'Raw Sales Data'!H13="BE-4402",125,'Raw Sales Data'!H13="BE-4408",58,'Raw Sales Data'!H13="SP-5501",1495,'Raw Sales Data'!H13="SP-5505",299,'Raw Sales Data'!H13="SP-5510",249)} -> 125 | L13: 2025-02-10 | M13: =K13*I13 -> 125 | N13: PayPal | O13: No
A14: VT-0011 | B14: 2025-02-10 | C14: February | D14: E002 | E14: Sarah Connor | F14: West | G14: Sports | H14: BE-4408 | I14: 2 | J14: E002 | K14: {=_xlfn.IFS(H14="EL-2201",999,'Raw Sales Data'!H14="EL-2205",1299,'Raw Sales Data'!H14="EL-2210",1099,'Raw Sales Data'!H14="CL-1102",89,'Raw Sales Data'!H14="CL-1108",79,'Raw Sales Data'!H14="CL-1120",95,'Raw Sales Data'!H14="HA-3301",549,'Raw Sales Data'!H14="HA-3305",399,'Raw Sales Data'!H14="HA-3308",129,'Raw Sales Data'!H14="BE-4401",42,'Raw Sales Data'!H14="BE-4402",125,'Raw Sales Data'!H14="BE-4408",58,'Raw Sales Data'!H14="SP-5501",1495,'Raw Sales Data'!H14="SP-5505",299,'Raw Sales Data'!H14="SP-5510",249)} -> 58 | L14: 2025-02-14 | M14: =K14*I14 -> 116 | N14: Debit Card | O14: Yes
A15: VT-0012 | B15: 2025-02-13 | C15: February | D15: E003 | E15: Mike Johnson | F15: North | G15: Electronics | H15: SP-5501 | I15: 1 | J15: E003 | K15: {=_xlfn.IFS(H15="EL-2201",999,'Raw Sales Data'!H15="EL-2205",1299,'Raw Sales Data'!H15="EL-2210",1099,'Raw Sales Data'!H15="CL-1102",89,'Raw Sales Data'!H15="CL-1108",79,'Raw Sales Data'!H15="CL-1120",95,'Raw Sales Data'!H15="HA-3301",549,'Raw Sales Data'!H15="HA-3305",399,'Raw Sales Data'!H15="HA-3308",129,'Raw Sales Data'!H15="BE-4401",42,'Raw Sales Data'!H15="BE-4402",125,'Raw Sales Data'!H15="BE-4408",58,'Raw Sales Data'!H15="SP-5501",1495,'Raw Sales Data'!H15="SP-5505",299,'Raw Sales Data'!H15="SP-5510",249)} -> 1495 | L15: 2025-02-18 | M15: =K15*I15 -> 1495 | N15: Credit Card | O15: No
... A19: VT-0016 | B19: 2025-02-25 | C19: February | D19: E007 | E19: David Lee | F19: South | G19: Clothing | H19: EL-2205 | I19: 1 | J19: E007 | K19: {=_xlfn.IFS(H19="EL-2201",999,'Raw Sales Data'!H19="EL-2205",1299,'Raw Sales Data'!H19="EL-2210",1099,'Raw Sales Data'!H19="CL-1102",89,'Raw Sales Data'!H19="CL-1108",79,'Raw Sales Data'!H19="CL-1120",95,'Raw Sales Data'!H19="HA-3301",549,'Raw Sales Data'!H19="HA-3305",399,'Raw Sales Data'!H19="HA-3308",129,'Raw Sales Data'!H19="BE-4401",42,'Raw Sales Data'!H19="BE-4402",125,'Raw Sales Data'!H19="BE-4408",58,'Raw Sales Data'!H19="SP-5501",1495,'Raw Sales Data'!H19="SP-5505",299,'Raw Sales Data'!H19="SP-5510",249)} -> 1299 | L19: 2025-02-28 | M19: =K19*I19 -> 1299 | N19: PayPal | O19: No
A20: VT-0017 | B20: 2025-03-04 | C20: March | D20: E008 | E20: Jennifer Taylor | F20: South | G20: Clothing | H20: EL-2210 | I20: 1 | J20: E008 | K20: {=_xlfn.IFS(H20="EL-2201",999,'Raw Sales Data'!H20="EL-2205",1299,'Raw Sales Data'!H20="EL-2210",1099,'Raw Sales Data'!H20="CL-1102",89,'Raw Sales Data'!H20="CL-1108",79,'Raw Sales Data'!H20="CL-1120",95,'Raw Sales Data'!H20="HA-3301",549,'Raw Sales Data'!H20="HA-3305",399,'Raw Sales Data'!H20="HA-3308",129,'Raw Sales Data'!H20="BE-4401",42,'Raw Sales Data'!H20="BE-4402",125,'Raw Sales Data'!H20="BE-4408",58,'Raw Sales Data'!H20="SP-5501",1495,'Raw Sales Data'!H20="SP-5505",299,'Raw Sales Data'!H20="SP-5510",249)} -> 1099 | L20: 2025-03-09 | M20: =K20*I20 -> 1099 | N20: Debit Card | O20: No
A21: VT-0018 | B21: 2025-03-07 | C21: March | D21: E009 | E21: Chris Anderson | F21: South | G21: Home Appliances | H21: CL-1102 | I21: 1 | J21: E009 | K21: {=_xlfn.IFS(H21="EL-2201",999,'Raw Sales Data'!H21="EL-2205",1299,'Raw Sales Data'!H21="EL-2210",1099,'Raw Sales Data'!H21="CL-1102",89,'Raw Sales Data'!H21="CL-1108",79,'Raw Sales Data'!H21="CL-1120",95,'Raw Sales Data'!H21="HA-3301",549,'Raw Sales Data'!H21="HA-3305",399,'Raw Sales Data'!H21="HA-3308",129,'Raw Sales Data'!H21="BE-4401",42,'Raw Sales Data'!H21="BE-4402",125,'Raw Sales Data'!H21="BE-4408",58,'Raw Sales Data'!H21="SP-5501",1495,'Raw Sales Data'!H21="SP-5505",299,'Raw Sales Data'!H21="SP-5510",249)} -> 89 | L21: 2025-03-11 | M21: =K21*I21 -> 89 | N21: Credit Card | O21: No
A22: VT-0019 | B22: 2025-03-10 | C22: March | D22: E010 | E22: Amanda Thomas | F22: East | G22: Home Appliances | H22: CL-1108 | I22: 2 | J22: E010 | K22: {=_xlfn.IFS(H22="EL-2201",999,'Raw Sales Data'!H22="EL-2205",1299,'Raw Sales Data'!H22="EL-2210",1099,'Raw Sales Data'!H22="CL-1102",89,'Raw Sales Data'!H22="CL-1108",79,'Raw Sales Data'!H22="CL-1120",95,'Raw Sales Data'!H22="HA-3301",549,'Raw Sales Data'!H22="HA-3305",399,'Raw Sales Data'!H22="HA-3308",129,'Raw Sales Data'!H22="BE-4401",42,'Raw Sales Data'!H22="BE-4402",125,'Raw Sales Data'!H22="BE-4408",58,'Raw Sales Data'!H22="SP-5501",1495,'Raw Sales Data'!H22="SP-5505",299,'Raw Sales Data'!H22="SP-5510",249)} -> 79 | L22: 2025-03-13 | M22: =K22*I22 -> 158 | N22: PayPal | O22: No
A23: VT-0020 | B23: 2025-03-13 | C23: March | D23: E001 | E23: James Wilson | F23: East | G23: Beauty | H23: CL-1120 | I23: 1 | J23: E001 | K23: {=_xlfn.IFS(H23="EL-2201",999,'Raw Sales Data'!H23="EL-2205",1299,'Raw Sales Data'!H23="EL-2210",1099,'Raw Sales Data'!H23="CL-1102",89,'Raw Sales Data'!H23="CL-1108",79,'Raw Sales Data'!H23="CL-1120",95,'Raw Sales Data'!H23="HA-3301",549,'Raw Sales Data'!H23="HA-3305",399,'Raw Sales Data'!H23="HA-3308",129,'Raw Sales Data'!H23="BE-4401",42,'Raw Sales Data'!H23="BE-4402",125,'Raw Sales Data'!H23="BE-4408",58,'Raw Sales Data'!H23="SP-5501",1495,'Raw Sales Data'!H23="SP-5505",299,'Raw Sales Data'!H23="SP-5510",249)} -> 95 | L23: 2025-03-16 | M23: =K23*I23 -> 95 | N23: Debit Card | O23: No
A24: VT-0021 | B24: 2025-03-16 | C24: March | D24: E002 | E24: Sarah Connor | F24: East | G24: Beauty | H24: HA-3301 | I24: 2 | J24: E002 | K24: {=_xlfn.IFS(H24="EL-2201",999,'Raw Sales Data'!H24="EL-2205",1299,'Raw Sales Data'!H24="EL-2210",1099,'Raw Sales Data'!H24="CL-1102",89,'Raw Sales Data'!H24="CL-1108",79,'Raw Sales Data'!H24="CL-1120",95,'Raw Sales Data'!H24="HA-3301",549,'Raw Sales Data'!H24="HA-3305",399,'Raw Sales Data'!H24="HA-3308",129,'Raw Sales Data'!H24="BE-4401",42,'Raw Sales Data'!H24="BE-4402",125,'Raw Sales Data'!H24="BE-4408",58,'Raw Sales Data'!H24="SP-5501",1495,'Raw Sales Data'!H24="SP-5505",299,'Raw Sales Data'!H24="SP-5510",249)} -> 549 | L24: 2025-03-20 | M24: =K24*I24 -> 1098 | N24: Credit Card | O24: No
A25: VT-0022 | B25: 2025-03-19 | C25: March | D25: E003 | E25: Mike Johnson | F25: West | G25: Sports | H25: HA-3305 | I25: 1 | J25: E003 | K25: {=_xlfn.IFS(H25="EL-2201",999,'Raw Sales Data'!H25="EL-2205",1299,'Raw Sales Data'!H25="EL-2210",1099,'Raw Sales Data'!H25="CL-1102",89,'Raw Sales Data'!H25="CL-1108",79,'Raw Sales Data'!H25="CL-1120",95,'Raw Sales Data'!H25="HA-3301",549,'Raw Sales Data'!H25="HA-3305",399,'Raw Sales Data'!H25="HA-3308",129,'Raw Sales Data'!H25="BE-4401",42,'Raw Sales Data'!H25="BE-4402",125,'Raw Sales Data'!H25="BE-4408",58,'Raw Sales Data'!H25="SP-5501",1495,'Raw Sales Data'!H25="SP-5505",299,'Raw Sales Data'!H25="SP-5510",249)} -> 399 | L25: 2025-03-24 | M25: =K25*I25 -> 399 | N25: PayPal | O25: Yes
A26: VT-0023 | B26: 2025-03-22 | C26: March | D26: E004 | E26: Emily Davis | F26: West | G26: Sports | H26: HA-3308 | I26: 3 | J26: E004 | K26: {=_xlfn.IFS(H26="EL-2201",999,'Raw Sales Data'!H26="EL-2205",1299,'Raw Sales Data'!H26="EL-2210",1099,'Raw Sales Data'!H26="CL-1102",89,'Raw Sales Data'!H26="CL-1108",79,'Raw Sales Data'!H26="CL-1120",95,'Raw Sales Data'!H26="HA-3301",549,'Raw Sales Data'!H26="HA-3305",399,'Raw Sales Data'!H26="HA-3308",129,'Raw Sales Data'!H26="BE-4401",42,'Raw Sales Data'!H26="BE-4402",125,'Raw Sales Data'!H26="BE-4408",58,'Raw Sales Data'!H26="SP-5501",1495,'Raw Sales Data'!H26="SP-5505",299,'Raw Sales Data'!H26="SP-5510",249)} -> 129 | L26: 2025-03-25 | M26: =K26*I26 -> 387 | N26: Debit Card | O26: No
A27: VT-0024 | B27: 2025-03-25 | C27: March | D27: E005 | E27: Robert Brown | F27: North | G27: Electronics | H27: BE-4401 | I27: 1 | J27: E005 | K27: {=_xlfn.IFS(H27="EL-2201",999,'Raw Sales Data'!H27="EL-2205",1299,'Raw Sales Data'!H27="EL-2210",1099,'Raw Sales Data'!H27="CL-1102",89,'Raw Sales Data'!H27="CL-1108",79,'Raw Sales Data'!H27="CL-1120",95,'Raw Sales Data'!H27="HA-3301",549,'Raw Sales Data'!H27="HA-3305",399,'Raw Sales Data'!H27="HA-3308",129,'Raw Sales Data'!H27="BE-4401",42,'Raw Sales Data'!H27="BE-4402",125,'Raw Sales Data'!H27="BE-4408",58,'Raw Sales Data'!H27="SP-5501",1495,'Raw Sales Data'!H27="SP-5505",299,'Raw Sales Data'!H27="SP-5510",249)} -> 42 | L27: 2025-03-22 | M27: =K27*I27 -> 42 | N27: Credit Card | O27: No
A28: VT-0025 | B28: 2025-04-04 | C28: April | D28: E006 | E28: Lisa Martinez | F28: North | G28: Electronics | H28: BE-4402 | I28: 2 | J28: E006 | K28: {=_xlfn.IFS(H28="EL-2201",999,'Raw Sales Data'!H28="EL-2205",1299,'Raw Sales Data'!H28="EL-2210",1099,'Raw Sales Data'!H28="CL-1102",89,'Raw Sales Data'!H28="CL-1108",79,'Raw Sales Data'!H28="CL-1120",95,'Raw Sales Data'!H28="HA-3301",549,'Raw Sales Data'!H28="HA-3305",399,'Raw Sales Data'!H28="HA-3308",129,'Raw Sales Data'!H28="BE-4401",42,'Raw Sales Data'!H28="BE-4402",125,'Raw Sales Data'!H28="BE-4408",58,'Raw Sales Data'!H28="SP-5501",1495,'Raw Sales Data'!H28="SP-5505",299,'Raw Sales Data'!H28="SP-5510",249)} -> 125 | L28: 2025-04-08 | M28: =K28*I28 -> 250 | N28: PayPal | O28: No
A29: VT-0026 | B29: 2025-04-07 | C29: April | D29: E007 | E29: David Lee | F29: North | G29: Electronics | H29: BE-4408 | I29: 1 | J29: E007 | K29: {=_xlfn.IFS(H29="EL-2201",999,'Raw Sales Data'!H29="EL-2205",1299,'Raw Sales Data'!H29="EL-2210",1099,'Raw Sales Data'!H29="CL-1102",89,'Raw Sales Data'!H29="CL-1108",79,'Raw Sales Data'!H29="CL-1120",95,'Raw Sales Data'!H29="HA-3301",549,'Raw Sales Data'!H29="HA-3305",399,'Raw Sales Data'!H29="HA-3308",129,'Raw Sales Data'!H29="BE-4401",42,'Raw Sales Data'!H29="BE-4402",125,'Raw Sales Data'!H29="BE-4408",58,'Raw Sales Data'!H29="SP-5501",1495,'Raw Sales Data'!H29="SP-5505",299,'Raw Sales Data'!H29="SP-5510",249)} -> 58 | L29: 2025-04-10 | M29: =K29*I29 -> 58 | N29: Debit Card | O29: No
A30: VT-0027 | B30: 2025-04-10 | C30: April | D30: E008 | E30: Jennifer Taylor | F30: North | G30: Electronics | H30: SP-5501 | I30: 1 | J30: E008 | K30: {=_xlfn.IFS(H30="EL-2201",999,'Raw Sales Data'!H30="EL-2205",1299,'Raw Sales Data'!H30="EL-2210",1099,'Raw Sales Data'!H30="CL-1102",89,'Raw Sales Data'!H30="CL-1108",79,'Raw Sales Data'!H30="CL-1120",95,'Raw Sales Data'!H30="HA-3301",549,'Raw Sales Data'!H30="HA-3305",399,'Raw Sales Data'!H30="HA-3308",129,'Raw Sales Data'!H30="BE-4401",42,'Raw Sales Data'!H30="BE-4402",125,'Raw Sales Data'!H30="BE-4408",58,'Raw Sales Data'!H30="SP-5501",1495,'Raw Sales Data'!H30="SP-5505",299,'Raw Sales Data'!H30="SP-5510",249)} -> 1495 | L30: 2025-04-15 | M30: =K30*I30 -> 1495 | N30: Credit Card | O30: No
A31: VT-0028 | B31: 2025-04-13 | C31: April | D31: E009 | E31: Chris Anderson | F31: South | G31: Clothing | H31: SP-5505 | I31: 1 | J31: E009 | K31: {=_xlfn.IFS(H31="EL-2201",999,'Raw Sales Data'!H31="EL-2205",1299,'Raw Sales Data'!H31="EL-2210",1099,'Raw Sales Data'!H31="CL-1102",89,'Raw Sales Data'!H31="CL-1108",79,'Raw Sales Data'!H31="CL-1120",95,'Raw Sales Data'!H31="HA-3301",549,'Raw Sales Data'!H31="HA-3305",399,'Raw Sales Data'!H31="HA-3308",129,'Raw Sales Data'!H31="BE-4401",42,'Raw Sales Data'!H31="BE-4402",125,'Raw Sales Data'!H31="BE-4408",58,'Raw Sales Data'!H31="SP-5501",1495,'Raw Sales Data'!H31="SP-5505",299,'Raw Sales Data'!H31="SP-5510",249)} -> 299 | L31: 2025-04-17 | M31: =K31*I31 -> 299 | N31: PayPal | O31: No
A32: VT-0029 | B32: 2025-04-16 | C32: April | D32: E010 | E32: Amanda Thomas | F32: South | G32: Clothing | H32: SP-5510 | I32: 2 | J32: E010 | K32: {=_xlfn.IFS(H32="EL-2201",999,'Raw Sales Data'!H32="EL-2205",1299,'Raw Sales Data'!H32="EL-2210",1099,'Raw Sales Data'!H32="CL-1102",89,'Raw Sales Data'!H32="CL-1108",79,'Raw Sales Data'!H32="CL-1120",95,'Raw Sales Data'!H32="HA-3301",549,'Raw Sales Data'!H32="HA-3305",399,'Raw Sales Data'!H32="HA-3308",129,'Raw Sales Data'!H32="BE-4401",42,'Raw Sales Data'!H32="BE-4402",125,'Raw Sales Data'!H32="BE-4408",58,'Raw Sales Data'!H32="SP-5501",1495,'Raw Sales Data'!H32="SP-5505",299,'Raw Sales Data'!H32="SP-5510",249)} -> 249 | L32: 2025-04-19 | M32: =K32*I32 -> 498 | N32: Debit Card | O32: No
A33: VT-0030 | B33: 2025-04-19 | C33: April | D33: E001 | E33: James Wilson | F33: South | G33: Home Appliances | H33: EL-2201 | I33: 1 | J33: E001 | K33: {=_xlfn.IFS(H33="EL-2201",999,'Raw Sales Data'!H33="EL-2205",1299,'Raw Sales Data'!H33="EL-2210",1099,'Raw Sales Data'!H33="CL-1102",89,'Raw Sales Data'!H33="CL-1108",79,'Raw Sales Data'!H33="CL-1120",95,'Raw Sales Data'!H33="HA-3301",549,'Raw Sales Data'!H33="HA-3305",399,'Raw Sales Data'!H33="HA-3308",129,'Raw Sales Data'!H33="BE-4401",42,'Raw Sales Data'!H33="BE-4402",125,'Raw Sales Data'!H33="BE-4408",58,'Raw Sales Data'!H33="SP-5501",1495,'Raw Sales Data'!H33="SP-5505",299,'Raw Sales Data'!H33="SP-5510",249)} -> 999 | L33: 2025-04-22 | M33: =K33*I33 -> 999 | N33: Credit Card | O33: No
A34: VT-0031 | B34: 2025-04-22 | C34: April | D34: E002 | E34: Sarah Connor | F34: East | G34: Home Appliances | H34: EL-2205 | I34: 2 | J34: E002 | K34: {=_xlfn.IFS(H34="EL-2201",999,'Raw Sales Data'!H34="EL-2205",1299,'Raw Sales Data'!H34="EL-2210",1099,'Raw Sales Data'!H34="CL-1102",89,'Raw Sales Data'!H34="CL-1108",79,'Raw Sales Data'!H34="CL-1120",95,'Raw Sales Data'!H34="HA-3301",549,'Raw Sales Data'!H34="HA-3305",399,'Raw Sales Data'!H34="HA-3308",129,'Raw Sales Data'!H34="BE-4401",42,'Raw Sales Data'!H34="BE-4402",125,'Raw Sales Data'!H34="BE-4408",58,'Raw Sales Data'!H34="SP-5501",1495,'Raw Sales Data'!H34="SP-5505",299,'Raw Sales Data'!H34="SP-5510",249)} -> 1299 | L34: 2025-04-26 | M34: =K34*I34 -> 2598 | N34: PayPal | O34: No
A35: VT-0032 | B35: 2025-04-25 | C35: April | D35: E003 | E35: Mike Johnson | F35: East | G35: Beauty | H35: EL-2210 | I35: 1 | J35: E003 | K35: {=_xlfn.IFS(H35="EL-2201",999,'Raw Sales Data'!H35="EL-2205",1299,'Raw Sales Data'!H35="EL-2210",1099,'Raw Sales Data'!H35="CL-1102",89,'Raw Sales Data'!H35="CL-1108",79,'Raw Sales Data'!H35="CL-1120",95,'Raw Sales Data'!H35="HA-3301",549,'Raw Sales Data'!H35="HA-3305",399,'Raw Sales Data'!H35="HA-3308",129,'Raw Sales Data'!H35="BE-4401",42,'Raw Sales Data'!H35="BE-4402",125,'Raw Sales Data'!H35="BE-4408",58,'Raw Sales Data'!H35="SP-5501",1495,'Raw Sales Data'!H35="SP-5505",299,'Raw Sales Data'!H35="SP-5510",249)} -> 1099 | L35: 2025-04-28 | M35: =K35*I35 -> 1099 | N35: Debit Card | O35: No
A36: VT-0033 | B36: 2025-05-04 | C36: May | D36: E004 | E36: Emily Davis | F36: East | G36: Beauty | H36: CL-1102 | I36: 3 | J36: E004 | K36: {=_xlfn.IFS(H36="EL-2201",999,'Raw Sales Data'!H36="EL-2205",1299,'Raw Sales Data'!H36="EL-2210",1099,'Raw Sales Data'!H36="CL-1102",89,'Raw Sales Data'!H36="CL-1108",79,'Raw Sales Data'!H36="CL-1120",95,'Raw Sales Data'!H36="HA-3301",549,'Raw Sales Data'!H36="HA-3305",399,'Raw Sales Data'!H36="HA-3308",129,'Raw Sales Data'!H36="BE-4401",42,'Raw Sales Data'!H36="BE-4402",125,'Raw Sales Data'!H36="BE-4408",58,'Raw Sales Data'!H36="SP-5501",1495,'Raw Sales Data'!H36="SP-5505",299,'Raw Sales Data'!H36="SP-5510",249)} -> 89 | L36: 2025-05-07 | M36: =K36*I36 -> 267 | N36: Credit Card | O36: Yes
A37: VT-0034 | B37: 2025-05-07 | C37: May | D37: E005 | E37: Robert Brown | F37: West | G37: Sports | H37: CL-1108 | I37: 1 | J37: E005 | K37: {=_xlfn.IFS(H37="EL-2201",999,'Raw Sales Data'!H37="EL-2205",1299,'Raw Sales Data'!H37="EL-2210",1099,'Raw Sales Data'!H37="CL-1102",89,'Raw Sales Data'!H37="CL-1108",79,'Raw Sales Data'!H37="CL-1120",95,'Raw Sales Data'!H37="HA-3301",549,'Raw Sales Data'!H37="HA-3305",399,'Raw Sales Data'!H37="HA-3308",129,'Raw Sales Data'!H37="BE-4401",42,'Raw Sales Data'!H37="BE-4402",125,'Raw Sales Data'!H37="BE-4408",58,'Raw Sales Data'!H37="SP-5501",1495,'Raw Sales Data'!H37="SP-5505",299,'Raw Sales Data'!H37="SP-5510",249)} -> 79 | L37: 2025-05-04 | M37: =K37*I37 -> 79 | N37: PayPal | O37: No
A38: VT-0035 | B38: 2025-05-10 | C38: May | D38: E006 | E38: Lisa Martinez | F38: West | G38: Sports | H38: CL-1120 | I38: 2 | J38: E006 | K38: {=_xlfn.IFS(H38="EL-2201",999,'Raw Sales Data'!H38="EL-2205",1299,'Raw Sales Data'!H38="EL-2210",1099,'Raw Sales Data'!H38="CL-1102",89,'Raw Sales Data'!H38="CL-1108",79,'Raw Sales Data'!H38="CL-1120",95,'Raw Sales Data'!H38="HA-3301",549,'Raw Sales Data'!H38="HA-3305",399,'Raw Sales Data'!H38="HA-3308",129,'Raw Sales Data'!H38="BE-4401",42,'Raw Sales Data'!H38="BE-4402",125,'Raw Sales Data'!H38="BE-4408",58,'Raw Sales Data'!H38="SP-5501",1495,'Raw Sales Data'!H38="SP-5505",299,'Raw Sales Data'!H38="SP-5510",249)} -> 95 | L38: 2025-05-14 | M38: =K38*I38 -> 190 | N38: Debit Card | O38: No
A39: VT-0036 | B39: 2025-05-13 | C39: May | D39: E007 | E39: David Lee | F39: North | G39: Electronics | H39: HA-3301 | I39: 1 | J39: E007 | K39: {=_xlfn.IFS(H39="EL-2201",999,'Raw Sales Data'!H39="EL-2205",1299,'Raw Sales Data'!H39="EL-2210",1099,'Raw Sales Data'!H39="CL-1102",89,'Raw Sales Data'!H39="CL-1108",79,'Raw Sales Data'!H39="CL-1120",95,'Raw Sales Data'!H39="HA-3301",549,'Raw Sales Data'!H39="HA-3305",399,'Raw Sales Data'!H39="HA-3308",129,'Raw Sales Data'!H39="BE-4401",42,'Raw Sales Data'!H39="BE-4402",125,'Raw Sales Data'!H39="BE-4408",58,'Raw Sales Data'!H39="SP-5501",1495,'Raw Sales Data'!H39="SP-5505",299,'Raw Sales Data'!H39="SP-5510",249)} -> 549 | L39: 2025-05-16 | M39: =K39*I39 -> 549 | N39: Credit Card | O39: No
A40: VT-0037 | B40: 2025-05-16 | C40: May | D40: E008 | E40: Jennifer Taylor | F40: North | G40: Electronics | H40: HA-3305 | I40: 1 | J40: E008 | K40: {=_xlfn.IFS(H40="EL-2201",999,'Raw Sales Data'!H40="EL-2205",1299,'Raw Sales Data'!H40="EL-2210",1099,'Raw Sales Data'!H40="CL-1102",89,'Raw Sales Data'!H40="CL-1108",79,'Raw Sales Data'!H40="CL-1120",95,'Raw Sales Data'!H40="HA-3301",549,'Raw Sales Data'!H40="HA-3305",399,'Raw Sales Data'!H40="HA-3308",129,'Raw Sales Data'!H40="BE-4401",42,'Raw Sales Data'!H40="BE-4402",125,'Raw Sales Data'!H40="BE-4408",58,'Raw Sales Data'!H40="SP-5501",1495,'Raw Sales Data'!H40="SP-5505",299,'Raw Sales Data'!H40="SP-5510",249)} -> 399 | L40: 2025-05-21 | M40: =K40*I40 -> 399 | N40: PayPal | O40: No
A41: VT-0038 | B41: 2025-05-19 | C41: May | D41: E009 | E41: Chris Anderson | F41: North | G41: Electronics | H41: HA-3308 | I41: 1 | J41: E009 | K41: {=_xlfn.IFS(H41="EL-2201",999,'Raw Sales Data'!H41="EL-2205",1299,'Raw Sales Data'!H41="EL-2210",1099,'Raw Sales Data'!H41="CL-1102",89,'Raw Sales Data'!H41="CL-1108",79,'Raw Sales Data'!H41="CL-1120",95,'Raw Sales Data'!H41="HA-3301",549,'Raw Sales Data'!H41="HA-3305",399,'Raw Sales Data'!H41="HA-3308",129,'Raw Sales Data'!H41="BE-4401",42,'Raw Sales Data'!H41="BE-4402",125,'Raw Sales Data'!H41="BE-4408",58,'Raw Sales Data'!H41="SP-5501",1495,'Raw Sales Data'!H41="SP-5505",299,'Raw Sales Data'!H41="SP-5510",249)} -> 129 | L41: 2025-05-23 | M41: =K41*I41 -> 129 | N41: Debit Card | O41: No
A42: VT-0039 | B42: 2025-05-22 | C42: May | D42: E010 | E42: Amanda Thomas | F42: North | G42: Electronics | H42: BE-4401 | I42: 2 | J42: E010 | K42: {=_xlfn.IFS(H42="EL-2201",999,'Raw Sales Data'!H42="EL-2205",1299,'Raw Sales Data'!H42="EL-2210",1099,'Raw Sales Data'!H42="CL-1102",89,'Raw Sales Data'!H42="CL-1108",79,'Raw Sales Data'!H42="CL-1120",95,'Raw Sales Data'!H42="HA-3301",549,'Raw Sales Data'!H42="HA-3305",399,'Raw Sales Data'!H42="HA-3308",129,'Raw Sales Data'!H42="BE-4401",42,'Raw Sales Data'!H42="BE-4402",125,'Raw Sales Data'!H42="BE-4408",58,'Raw Sales Data'!H42="SP-5501",1495,'Raw Sales Data'!H42="SP-5505",299,'Raw Sales Data'!H42="SP-5510",249)} -> 42 | L42: 2025-05-25 | M42: =K42*I42 -> 84 | N42: Credit Card | O42: No
A43: VT-0040 | B43: 2025-05-25 | C43: May | D43: E001 | E43: James Wilson | F43: South | G43: Clothing | H43: BE-4402 | I43: 1 | J43: E001 | K43: {=_xlfn.IFS(H43="EL-2201",999,'Raw Sales Data'!H43="EL-2205",1299,'Raw Sales Data'!H43="EL-2210",1099,'Raw Sales Data'!H43="CL-1102",89,'Raw Sales Data'!H43="CL-1108",79,'Raw Sales Data'!H43="CL-1120",95,'Raw Sales Data'!H43="HA-3301",549,'Raw Sales Data'!H43="HA-3305",399,'Raw Sales Data'!H43="HA-3308",129,'Raw Sales Data'!H43="BE-4401",42,'Raw Sales Data'!H43="BE-4402",125,'Raw Sales Data'!H43="BE-4408",58,'Raw Sales Data'!H43="SP-5501",1495,'Raw Sales Data'!H43="SP-5505",299,'Raw Sales Data'!H43="SP-5510",249)} -> 125 | L43: 2025-05-28 | M43: =K43*I43 -> 125 | N43: PayPal | O43: No
...

Sheet Product Master
A1: Product Master — Lookup Source for Phase 3
A3: Product Code | B3: Product Name | C3: Category | D3: Unit Price ($)
A4: EL-2201 | B4: iPhone 15 | C4: Electronics | D4: 999
A5: EL-2205 | B5: Samsung TV | C5: Electronics | D5: 1299
A6: EL-2210 | B6: Dell Laptop | C6: Electronics | D6: 1099
A7: CL-1102 | B7: Nike Hoodie | C7: Clothing | D7: 89
A8: CL-1108 | B8: Levi Jeans | C8: Clothing | D8: 79
A9: CL-1120 | B9: Ralph Lauren Polo | C9: Clothing | D9: 95
A10: HA-3301 | B10: Dyson Vacuum | C10: Home Appliances | D10: 549
A11: HA-3305 | B11: KitchenAid Mixer | C11: Home Appliances | D11: 399
A12: HA-3308 | B12: Instant Pot | C12: Home Appliances | D12: 129
A13: BE-4401 | B13: Fenty Foundation | C13: Beauty | D13: 42
A14: BE-4402 | B14: Dior Perfume | C14: Beauty | D14: 125
A15: BE-4408 | B15: Urban Decay Palette | C15: Beauty | D15: 58
... A18: SP-5510 | B18: Yeti Cooler | C18: Sports | D18: 249

Sheet Employee Master
A1: Employee Master — Lookup Source for Phase 3
A3: Employee ID | B3: Employee Name | C3: Department | D3: Years With Company
A4: E001 | B4: James Wilson | C4: Sales | D4: 5
A5: E002 | B5: Sarah Connor | C5: Sales | D5: 3
A6: E003 | B6: Mike Johnson | C6: Sales | D6: 7
A7: E004 | B7: Emily Davis | C7: Sales | D7: 2
A8: E005 | B8: Robert Brown | C8: Sales | D8: 9
A9: E006 | B9: Lisa Martinez | C9: Sales | D9: 4
A10: E007 | B10: David Lee | C10: Sales | D10: 6
A11: E008 | B11: Jennifer Taylor | C11: Sales | D11: 3
A12: E009 | B12: Chris Anderson | C12: Sales | D12: 4
A13: E010 | B13: Amanda Thomas | C13: Sales | D13: 8

Sheet Phase 1-2 Workspace
A1: Phase 1-2 — Cleaning and Validation Workspace
A2: Build helper columns here referencing 'Raw Sales Data'. Every formula type is one you've already used in Weeks 1, 2, and 7.
A4: Order ID | B4: Task | C4: Your Formula | D4: Result
A5: =OFFSET('Raw Sales Data'!A4,0,0) -> VT-0001 | B5: Clean Rep Name | C5: TRIM(PROPER('Raw Sales Data'!D4:D99)) | D5: TRIM + PROPER the raw name — Week 7 skill
A6: =OFFSET('Raw Sales Data'!A4,1,0) -> VT-0002 | B6: Standardize Region | C6: didn't do it with any signle formula i first standardize the region with trim+text then used pivot table to get know if there is any other value except North, East, West, South then N. region came out which was actually north so I used built-in find and replace tool and replaced N. with North | D6: Fix North/north/NORTH/N. into one consistent value — Week 7 + Week 2 skill
A7: =OFFSET('Raw Sales Data'!A4,2,0) -> VT-0003 | B7: Standardize Category | C7: Same as standardizing category I first cleaned the category with trim+Proper then used pivot table and Elect. Came out which I repaced with find and replace tool both region and category replacement can be done with substitute but it takes to copy or dragging out the entire column values to apply formula | D7: Fix Electronics/electronics/Elect. into one consistent value — Week 7 skill
A8: =OFFSET('Raw Sales Data'!A4,3,0) -> VT-0004 | B8: Flag Negative Quantity | C8: COUNTIF('Raw Sales Data'!I4:I99,"<1") | D8: IF quantity < 0 return Quantity Error — Week 2 skill
A9: =OFFSET('Raw Sales Data'!A4,4,0) -> VT-0005 | B9: Flag Impossible Delivery Date | C9: IF('Raw Sales Data'!B4>'Raw Sales Data'!L4,"impossible","normal") | D9: IF delivery date < order date return Date Error — Week 2 skill
C10: COUNTIF(C9,"impossible")
A11: =OFFSET('Raw Sales Data'!A4,5,0) -> VT-0006 | B11: Flag Duplicate Order | C11: IF(COUNTIFS('Raw Sales Data'!A4:L99,'Raw Sales Data'!D4,'Raw Sales Data'!A4:L99,'Raw Sales Data'!G4,'Raw Sales Data'!A4:L99,'Raw Sales Data'!J4)>1,"duplicate","normal") | D11: COUNTIFS on Rep + Product + Date > 1 return Duplicate — Week 2 + 7 skill
A13: For a real cleanup, build a helper column for EVERY row in Raw Sales Data (not just 6 examples above), then apply the same logic across all rows before moving to Phase 3.

Sheet Phase 3 Workspace
A1: Phase 3 — Enrichment with VLOOKUP / INDEX MATCH
A2: Pull Unit Price and Category from Product Master. Pull Department and Years With Company from Employee Master. Same logic as Week 3.
A4: Order ID | B4: What To Pull | C4: Source Sheet | D4: Your Formula
A5: VT-0001 | B5: Unit Price for this order's Product Code | C5: Product Master | D5: VLOOKUP(VLOOKUP(A5,'Raw Sales Data'!A4:L99,7,FALSE),'Product Master'!A4:D18,4,FALSE)
A6: VT-0001 | B6: Product Name for this order's Product Code | C6: Product Master | D6: VLOOKUP(VLOOKUP(A6,'Raw Sales Data'!A4:L99,7,FALSE),'Product Master'!A4:D18,2,FALSE)
A7: VT-0001 | B7: Employee Name for this order's Employee ID | C7: Employee Master | D7: VLOOKUP(VLOOKUP(A7,'Raw Sales Data'!A4:L99,9,FALSE),'Employee Master'!A4:D13,2,FALSE)
A8: VT-0001 | B8: Department for this order's Employee ID | C8: Employee Master | D8: VLOOKUP(VLOOKUP('Phase 3 Workspace'!A8,'Raw Sales Data'!A4:L99,9,FALSE),'Employee Master'!A4:D13,3,FALSE)
A9: VT-0001 | B9: Years With Company for this order's Employee ID | C9: Employee Master | D9: VLOOKUP(VLOOKUP(A9,'Raw Sales Data'!A4:L99,9,FALSE),'Employee Master'!A4:D13,4,FALSE)
B12: Nested Vlookup | D12: Vlookup + IndexMatch
B13: =VLOOKUP(VLOOKUP(A5,'Raw Sales Data'!A4:O99,8,FALSE),'Product Master'!A4:D18,4,FALSE) -> 1299 | D13: =(INDEX('Raw Sales Data'!A4:O99,MATCH('Phase 3 Workspace'!A5,'Raw Sales Data'!A4:A99,0),8)) -> EL-2205
B14: =VLOOKUP(VLOOKUP(A6,'Raw Sales Data'!A4:O99,8,FALSE),'Product Master'!A4:D18,2,FALSE) -> Samsung TV | D14: =VLOOKUP(D13,'Product Master'!A4:D18,4,FALSE) -> 1299
B15: =VLOOKUP(VLOOKUP(A7,'Raw Sales Data'!A4:O99,10,FALSE),'Employee Master'!A4:D13,2,FALSE) -> Sarah Connor | D15: =INDEX('Raw Sales Data'!A4:O99,MATCH('Phase 3 Workspace'!A6,'Raw Sales Data'!A4:A99,0),8) -> EL-2205
B16: =VLOOKUP(VLOOKUP('Phase 3 Workspace'!A8,'Raw Sales Data'!A4:O99,10,FALSE),'Employee Master'!A4:D13,3,FALSE) -> Sales | D16: =VLOOKUP(D15,'Product Master'!A4:D18,2,FALSE) -> Samsung TV
B17: =VLOOKUP(VLOOKUP(A9,'Raw Sales Data'!A4:O99,10,FALSE),'Employee Master'!A4:D13,4,FALSE) -> 3 | D17: =INDEX('Raw Sales Data'!A4:O99,MATCH('Phase 3 Workspace'!A7,'Raw Sales Data'!A4:A99,0),10) -> E002
D18: =VLOOKUP(D17,'Employee Master'!A4:D13,2,FALSE) -> Sarah Connor
D19: =INDEX('Raw Sales Data'!A4:O99,MATCH('Phase 3 Workspace'!A8,'Raw Sales Data'!A4:A99,0),10) -> E002
D20: =VLOOKUP(D19,'Employee Master'!A4:D13,3,FALSE) -> Sales
D21: =INDEX('Raw Sales Data'!A4:O99,MATCH('Phase 3 Workspace'!A9,'Raw Sales Data'!A4:A99,0),10) -> E002
D22: =VLOOKUP(D21,'Employee Master'!A4:D13,4,FALSE) -> 3

Sheet Executive Dashboard
A1: Vantree Retail Group — Annual Sales Review Dashboard
A3: KPI SUMMARY ROW — Build using SUMIFS / COUNTIFS / INDEX MATCH (Week 4 & 5)
A4: Total Revenue | B4: Total Orders | C4: Return Rate | D4: Top Region | E4: Top Rep | F4: Top Category
A5: =SUM('Raw Sales Data'!M4:M99) -> 60399 | B5: =COUNT('Raw Sales Data'!I4:I99) -> 88 | C5: =COUNTIF('Raw Sales Data'!O4:O99,"Yes")*B5/100 -> 7.04 | D5: North | E5: Sarah Connor | F5: Electronics | H5: Row Labels | I5: Sum of Revenue | J5: Row Labels | K5: Sum of Revenue
H6: North | I6: 25045 | J6: West | K6: 5787
A7: REQUIRED CHARTS — Build using Pivot Tables (Week 4) | H7: Grand Total | I7: 25045 | J7: South | K7: 12766
A8: Revenue by Region | D8: Bar chart, sorted highest to lowest | J8: East | K8: 16801
A9: Monthly Revenue Trend | D9: Line chart with trendline (Week 6) | H9: Row Labels | I9: Sum of Revenue | J9: North | K9: 25045
A10: Revenue by Category | D10: Bar or pie chart | H10: Sarah Connor | I10: 14034 | J10: Grand Total | K10: 60399
A11: Sales Rep Ranking | D11: Pivot table with Icon Sets (Week 4) | H11: Grand Total | I11: 14034
A12: Return Rate by Category | D12: Bar chart — which category has the most returns
H13: Row Labels | I13: Sum of Revenue
A14: EXECUTIVE SUMMARY — Write this entirely yourself, no AI drafting | H14: Electronics | I14: 25045
A15: Write 5-7 sentences here: What changed year over year? Which region or category needs attention? What is your one clear recommendation to the board? Summery: The Business Need some more detailed Seasonal, Regional and Category analysis the pattern drived form five KPIs doesn't really shows anything specific but some matrics. The North is performing on top and the most returned category is Electronics while the most revenue is also gained in Electronics means that the revenue is shown in Electronics isn't really the revenue business has got mostly products in Electronics are returned while the revenue by month is pretty fluctuated every second month is being dropped by the sharpest amount and every second month has sharpest spike this pattern can bring some valuable and actionable insights if the sentimental analysis for monthly trend is done in more depth. | H15: Grand Total | I15: 25045

Sheet Dashboard
A1: Vantree Retail Group - Annual Sales Analysis Dashboard
A3: Total Revenue | B3: Total Orders | C3: Return Rate | D3: Top Region | E3: Top Rep | F3: Top Category
A4: =SUM('Raw Sales Data'!M3:M98) -> 59850 | B4: =COUNT('Raw Sales Data'!I3:I98) -> 87 | C4: =COUNTIF('Raw Sales Data'!O3:O98,"Yes")*B4/100 -> 6.96 | D4: North | E4: Sarah Connor | F4: Electronics
A5: Top Bottom Sales Rap performance
A6: Sales Rep | B6: Revenue
A7: Sarah Connor | B7: 14034
A8: Mike Johnson | B8: 10078
A9: Jennifer Taylor | B9: 8979
A10: Amanda Thomas | B10: 2220
A11: Chris Anderson | B11: 1551
A12: Robert Brown | B12: 1189

Sheet AI Audit
A1: Week 8 — Final Project AI Audit Log
A2: This is the most important audit of Month 1-2. Give AI the FULL project brief, not individual formulas. See how it handles a multi-phase task versus a single formula.
A4: AUDIT 1 — Give AI the entire Phase 1-2 cleaning task at once. Does it handle all 6 sub-tasks correctly, or does it miss some?
A5: Task given to AI | B5: Phase 1-2 cleaning task at once
A6: Exact output AI produced | B6: TRIM(PROPER('Raw Sales Data'!D4:D99))
A7: Was AI correct? Yes / No / Partially | B7: Yes
A8: What was wrong or missing | B8: Nothing
A9: Error type: Range / Logic / Assumption / Generic output / Other | B9: Nothing
A10: How I caught it | B10: Comparing to my answer
A11: What this reveals about AI on multi-step business projects | B11: Since ai is Based on algorithms, statistics, systems, workflows it can understand and handle multi-step business projects very well but only if the command is clear only if there is clarity telling ai everything what it actually needs to do
A13: AUDIT 2 — Give AI the Phase 3 lookup task. Does it correctly choose VLOOKUP vs INDEX MATCH based on which direction it needs to look?
A14: Task given to AI | B14: Phase 3 lookup task
A15: Exact output AI produced | B15: VLOOKUP(VLOOKUP(A5,'Raw Sales Data'!A4:O99,8,FALSE),'Product Master'!A4:D18,4,FALSE), (INDEX('Raw Sales Data'!A4:O99,MATCH('Phase 3 Workspace'!A5,'Raw Sales Data'!A4:A99,0),8)) and VLOOKUP(D13,'Product Master'!A4:D18,4,FALSE)
A16: Was AI correct? Yes / No / Partially | B16: Yes
A17: What was wrong or missing | B17: Nothing
A18: Error type: Range / Logic / Assumption / Generic output / Other | B18: Nothing
A19: How I caught it | B19: Comparing with my answer
A20: What this reveals about AI on multi-step business projects | B20: Since ai is Based on algorithms, statistics, systems, workflows it can understand and handle multi-step business projects very well but only if the command is clear only if there is clarity telling ai everything what it actually needs to do
A22: AUDIT 3 — Ask AI to write the KPI Summary Row formulas. Check every single one against manual calculation.
A23: Task given to AI | B23: write the KPI Summary Row formulas
A24: Exact output AI produced | B24: SUM('Raw Sales Data'!M4:M99), COUNT('Raw Sales Data'!I4:I99), COUNTIF('Raw Sales Data'!O4:O99,"Yes")*B5/100, For Top Region, Top Rep, Top Category ai used pivot tables
A25: Was AI correct? Yes / No / Partially | B25: Yes
A26: What was wrong or missing | B26: Nothing
A27: Error type: Range / Logic / Assumption / Generic output / Other | B27: Nothing
A28: How I caught it | B28: Comparing to my answer
A29: What this reveals about AI on multi-step business projects | B29: Since ai is Based on algorithms, statistics, systems, workflows it can understand and handle multi-step business projects very well but only if the command is clear only if there is clarity telling ai everything what it actually needs to do
A31: AUDIT 4 — Ask AI to write the Executive Summary. Compare its version to yours — is it generic, or does it reflect the ACTUAL numbers in your dashboard?
A32: Task given to AI | B32: write the Executive Summary
A33: Exact output AI produced | B33: Year-over-year performance cannot be quantified from the supplied dashboard because it contains only one period of results and no prior-year comparison. Current revenue totals $59,850 across 87 orders, with a 6.96% return rate. The North region leads revenue at $25,045, while the West is the weakest at $5,787 and therefore needs the most attention. Electronics is the largest category at $25,045, but it also has the highest return-rate count shown, at 32, so margin quality and customer satisfaction warrant review. The South and East regions contribute $12,766 and $16,801 respectively, indicating that performance is concentrated in North and East. My recommendation to the board is to launch a focused West-region recovery plan while investigating Electronics returns before increasing investment in that category. Management should add prior-year revenue, orders, and return-rate data to the dashboard so future board decisions can be based on verified year-over-year trends.
A34: Was AI correct? Yes / No / Partially | B34: Yes
A35: What was wrong or missing | B35: Nothing
A36: Error type: Range / Logic / Assumption / Generic output / Other | B36: Nothing
A37: How I caught it | B37: Checking for every thing which is important in dashboard summery or executive summery
A38: What this reveals about AI on multi-step business projects | B38: This shows that ai can understand and implement the business context in professional way while keeping any specific scenerio as given
