Workbook

Sheet Raw Customer Data
A1: NEXACORE RETAIL — Raw Customer Feedback Export (Deliberately Messy)
A2: This is a raw export from Nexacore's customer feedback system. Messy on purpose — extra spaces, mixed case, combined fields, duplicate entries. Your job this week: clean it using text functions.
B3: Customer Name | C3: Email | D3: Region | E3: Store Code | F3: Product Code | G3: Product Name | H3: Feedback Text | I3: Rating | J3: Phone
A4: FB-001 | B4: James Wilson | C4: james.wilson@email.com | D4: NORTH | E4: NYC01 | F4: EL-2201 | G4: iPhone 15 | H4: Great Phone Works Well | I4: 5 | J4: 2125550198
A5: FB-002 | B5: Sarah Connor | C5: sarah.connor@email.com | D5: SOUTH | E5: LAX03 | F5: CL-1102 | G5: Nike Hoodie | H5: Love The Hoodie, Fits Perfect | I5: 5 | J5: 3105550142
A6: FB-003 | B6: Mike Johnson | C6: mike.johnson@email.com | D6: EAST | E6: HI02 | F6: HA-3301 | G6: Dyson Vacuum | H6: Product Broke After 2 Weeks!! | I6: 2 | J6: 3125550176
A7: FB-004 | B7: Emily Davis | C7: emily.davis@email.com | D7: WEST | E7: OU04 | F7: BE-4401 | G7: Fenty Foundation | H7: Perfect Shade Match | I7: 5 | J7: 7135550189
A8: FB-005 | B8: Robert Brown | C8: robert.brown@email.com | D8: NORTH | E8: NYC02 | F8: EL-2205 | G8: Samsung TV | H8: Screen Has Dead Pixels | I8: 1 | J8: 2125550201
A9: FB-006 | B9: Lisa Martinez | C9: lisa.martinez@email.com | D9: SOUTH | E9: LAX07 | F9: CL-1108 | G9: Levi Jeans | H9: Runs A Bit Small, Order Up A Size | I9: 4 | J9: 3105550155
A10: FB-007 | B10: David Lee | C10: david.lee@email.com | D10: EAST | E10: HI02 | F10: EL-2210 | G10: Dell Laptop | H10: Fast Delivery, Good Laptop | I10: 5 | J10: 3125550188
A11: FB-008 | B11: Jennifer Taylor | C11: jennifer.taylor@email.com | D11: EAST | E11: HI05 | F11: HA-3305 | G11: KitchenAid Mixer | H11: Exactly As Described | I11: 5 | J11: 3125550199
A12: FB-009 | B12: Chris Anderson | C12: chris.anderson@email.com | D12: WEST | E12: OU04 | F12: BE-4402 | G12: Dior Perfume | H12: Scent Doesn'T Last Long | I12: 3 | J12: 7135550167
A13: FB-010 | B13: Amanda Thomas | C13: amanda.thomas@email.com | D13: WEST | E13: OU06 | F13: EL-2201 | G13: iPhone 15 | H13: Great Phone Works Well | I13: 5 | J13: 7135550143
A14: FB-011 | B14: Joshua Jackson | C14: joshua.jackson@email.com | D14: NORTH | E14: NYC01 | F14: CL-1110 | G14: Jordan Sneakers | H14: Sizing Was Confusing | I14: 3 | J14: 2125550212
A15: FB-012 | B15: Ashley White | C15: ashley.white@email.com | D15: SOUTH | E15: LAX07 | F15: HA-3308 | G15: Instant Pot | H15: Works Great, Easy To Use | I15: 5 | J15: 3105550176
A16: FB-013 | B16: Matthew Harris | C16: matthew.harris@email.com | D16: SOUTH | E16: LAX03 | F16: EL-2215 | G16: Sony Headphones | H16: Sound Quality Is Excellent | I16: 5 | J16: 3105550188
... A21: FB-018 | B21: Michelle Lee | C21: michelle.lee@email.com | D21: SOUTH | E21: LAX07 | F21: BE-4408 | G21: Urban Decay Palette | H21: Beautiful Colors, Great Quality | I21: 5 | J21: 3105550199

Sheet Text Functions Practice
A1: Week 7 — Text Functions Practice
A2: Each function below fixes a specific real problem visible in Raw Customer Data. Learn the function by fixing the exact thing it's meant to fix.
A4: REFERENCE TABLE — What Each Function Actually Fixes
A5: Function | B5: What it does | C5: Real problem it fixes here | D5: Example
A6: TRIM | B6: Removes extra spaces from text — leading, trailing, and repeated spaces between words | C6: Customer Name column has names like ' james wilson ' with extra spaces | D6: =TRIM(B4)
A7: UPPER | B7: Converts all letters to uppercase | C7: Standardizing codes for comparison | D7: =UPPER(B4)
A8: LOWER | B8: Converts all letters to lowercase | C8: Standardizing emails which should always be lowercase | D8: =LOWER(C4)
A9: PROPER | B9: Capitalizes the first letter of each word | C9: Names typed in lowercase like 'james wilson' need proper capitalization | D9: =PROPER(B4)
A10: LEN | B10: Counts the number of characters in text | C10: Checking if phone numbers have the expected length after cleaning | D10: =LEN(H4)
A11: LEFT | B11: Extracts characters from the START of text, you choose how many | C11: Getting 'NORTH' out of 'NORTH-NYC01' | D11: =LEFT(D4,5)
A12: RIGHT | B12: Extracts characters from the END of text, you choose how many | C12: Getting the last 4 digits of a phone number | D12: =RIGHT(H4,4)
A13: MID | B13: Extracts characters from the MIDDLE of text — you choose start position and length | C13: Getting 'NYC01' out of 'NORTH-NYC01' | D13: =MID(D4,7,5)
A14: FIND | B14: Finds the position number where a specific character or text appears | C14: Finding WHERE the dash is in 'NORTH-NYC01' so LEFT/MID know where to cut | D14: =FIND("-",D4)
A15: SUBSTITUTE | B15: Replaces one piece of text with another, everywhere it appears | C15: Replacing dashes with spaces, or fixing a typo pattern across many cells | D15: =SUBSTITUTE(D4,"-"," ")
A16: CONCATENATE / & | B16: Joins multiple pieces of text together into one | C16: Combining cleaned First Name and Last Name back into one Full Name | D16: =B4&" "&C4

Sheet Cleaning Workspace
A1: Week 7 — Cleaning Workspace
A2: Reference 'Raw Customer Data' sheet. Build cleaned columns here using the text functions from the reference sheet. Yellow = your formulas.
A4: TASK 1 — Clean the Customer Name
A5: Fix: extra spaces (TRIM) + wrong capitalization (PROPER). Combine both in one formula: =PROPER(TRIM(cell))
A6: Entry ID | B6: Raw Name | C6: Your Cleaned Formula | D6: Result
A7: ='Raw Customer Data'!A4 -> FB-001 | B7: ='Raw Customer Data'!B4 -> James Wilson | C7: PROPER(TRIM('Raw Customer Data'!B4)) | D7: =PROPER(TRIM('Raw Customer Data'!B4)) -> James Wilson
A8: ='Raw Customer Data'!A5 -> FB-002 | B8: ='Raw Customer Data'!B5 -> Sarah Connor | C8: PROPER(TRIM('Raw Customer Data'!B5)) | D8: =PROPER(TRIM('Raw Customer Data'!B5)) -> Sarah Connor
A9: ='Raw Customer Data'!A6 -> FB-003 | B9: ='Raw Customer Data'!B6 -> Mike Johnson | C9: PROPER(TRIM('Raw Customer Data'!B6)) | D9: =PROPER(TRIM('Raw Customer Data'!B6)) -> Mike Johnson
A10: ='Raw Customer Data'!A7 -> FB-004 | B10: ='Raw Customer Data'!B7 -> Emily Davis | C10: PROPER(TRIM('Raw Customer Data'!B7)) | D10: =PROPER(TRIM('Raw Customer Data'!B7)) -> Emily Davis
A11: ='Raw Customer Data'!A8 -> FB-005 | B11: ='Raw Customer Data'!B8 -> Robert Brown | C11: PROPER(TRIM('Raw Customer Data'!B8)) | D11: =PROPER(TRIM('Raw Customer Data'!B8)) -> Robert Brown
A13: TASK 2 — Clean the Email (lowercase + trim)
A14: Entry ID | B14: Raw Email | C14: Your Cleaned Formula | D14: Result
A15: ='Raw Customer Data'!A4 -> FB-001 | B15: ='Raw Customer Data'!C4 -> james.wilson@email.com | C15: TRIM(LOWER('Raw Customer Data'!C4)) | D15: =TRIM(LOWER('Raw Customer Data'!C4)) -> james.wilson@email.com
A16: ='Raw Customer Data'!A5 -> FB-002 | B16: ='Raw Customer Data'!C5 -> sarah.connor@email.com | C16: LOWER(TRIM('Raw Customer Data'!C5)) | D16: =LOWER(TRIM('Raw Customer Data'!C5)) -> sarah.connor@email.com
A17: ='Raw Customer Data'!A6 -> FB-003 | B17: ='Raw Customer Data'!C6 -> mike.johnson@email.com | C17: TRIM(LOWER('Raw Customer Data'!C6)) | D17: =TRIM(LOWER('Raw Customer Data'!C6)) -> mike.johnson@email.com
A18: ='Raw Customer Data'!A7 -> FB-004 | B18: ='Raw Customer Data'!C7 -> emily.davis@email.com | C18: LOWER(TRIM('Raw Customer Data'!C7)) | D18: =LOWER(TRIM('Raw Customer Data'!C7)) -> emily.davis@email.com
A19: ='Raw Customer Data'!A8 -> FB-005 | B19: ='Raw Customer Data'!C8 -> robert.brown@email.com | C19: TRIM(LOWER('Raw Customer Data'!C8)) | D19: =TRIM(LOWER('Raw Customer Data'!C8)) -> robert.brown@email.com
D20: =TRIM(LOWER('Raw Customer Data'!C9)) -> lisa.martinez@email.com
A21: TASK 3 — Split Region-Store Code into TWO columns
A22: 'NORTH-NYC01' needs to become Region='NORTH' and Store Code='NYC01'. Step 1: find where the dash is with FIND. Step 2: use LEFT for Region, MID or RIGHT for Store Code.
A23: Entry ID | B23: Raw Combined | C23: Region Formula | D23: Store Code Formula
A24: ='Raw Customer Data'!A4 -> FB-001 | B24: ='Raw Customer Data'!E4 -> NYC01 | C24: LEFT('Raw Customer Data'!D4,5) | D24: MID('Raw Customer Data'!D4,7,5)
A25: ='Raw Customer Data'!A5 -> FB-002 | B25: ='Raw Customer Data'!E5 -> LAX03 | C25: LEFT('Raw Customer Data'!D5,5) | D25: MID('Raw Customer Data'!D5,7,5)
A26: ='Raw Customer Data'!A6 -> FB-003 | B26: ='Raw Customer Data'!E6 -> HI02 | C26: LEFT('Raw Customer Data'!D6,4) | D26: MID('Raw Customer Data'!D6,6,5)
A27: ='Raw Customer Data'!A7 -> FB-004 | B27: ='Raw Customer Data'!E7 -> OU04 | C27: LEFT('Raw Customer Data'!D7,4) | D27: MID('Raw Customer Data'!D7,6,5)
A28: ='Raw Customer Data'!A8 -> FB-005 | B28: ='Raw Customer Data'!E8 -> NYC02 | C28: LEFT('Raw Customer Data'!D8,5) | D28: MID('Raw Customer Data'!D8,7,5)
A30: TASK 4 — Extract Product Code and Product Name separately
A31: 'EL-2201 iPhone 15' needs Product Code='EL-2201' and Product Name='iPhone 15'. The space after the code is your split point — use FIND to locate it.
A32: Entry ID | B32: Raw Combined | C32: Product Code Formula | D32: Product Name Formula
A33: ='Raw Customer Data'!A4 -> FB-001 | B33: ='Raw Customer Data'!G4 -> iPhone 15 | C33: LEFT('Raw Customer Data'!E4,7) | D33: MID('Raw Customer Data'!E4,9,99)
A34: ='Raw Customer Data'!A5 -> FB-002 | B34: ='Raw Customer Data'!G5 -> Nike Hoodie | C34: LEFT('Raw Customer Data'!E5,7) | D34: MID('Raw Customer Data'!E5,9,99)
A35: ='Raw Customer Data'!A6 -> FB-003 | B35: ='Raw Customer Data'!G6 -> Dyson Vacuum | C35: LEFT('Raw Customer Data'!E6,7) | D35: MID('Raw Customer Data'!E6,9,99)
A36: ='Raw Customer Data'!A7 -> FB-004 | B36: ='Raw Customer Data'!G7 -> Fenty Foundation | C36: LEFT('Raw Customer Data'!E7,7) | D36: MID('Raw Customer Data'!E7,9,99)
A37: ='Raw Customer Data'!A8 -> FB-005 | B37: ='Raw Customer Data'!G8 -> Samsung TV | C37: LEFT('Raw Customer Data'!E8,7) | D37: MID('Raw Customer Data'!E8,9,99)
A39: TASK 5 — Standardize Phone Numbers
A40: Phone numbers appear as '212-555-0198', '310.555.0142', '(312) 555-0176' — three different formats for the same thing. Use SUBSTITUTE to remove dots, parentheses, and spaces, leaving only digits. Then decide on ONE consistent format.
A41: Entry ID | B41: Raw Phone | C41: Your Cleaning Formula | D41: Result
A42: ='Raw Customer Data'!A4 -> FB-001 | B42: ='Raw Customer Data'!J4 -> 2125550198 | C42: SUBSTITUTE('Raw Customer Data'!H4,"-","") | D42: =SUBSTITUTE('Raw Customer Data'!J4,"-"," ") -> 2125550198
A43: ='Raw Customer Data'!A5 -> FB-002 | B43: ='Raw Customer Data'!J5 -> 3105550142 | C43: SUBSTITUTE('Raw Customer Data'!H5,".","") | D43: =SUBSTITUTE('Raw Customer Data'!J5,"."," ") -> 3105550142
A44: ='Raw Customer Data'!A6 -> FB-003 | B44: ='Raw Customer Data'!J6 -> 3125550176 | C44: SUBSTITUTE('Raw Customer Data'!H6," ","") | D44: =SUBSTITUTE('Raw Customer Data'!J6,"-"," ") -> 3125550176
...

Sheet Duplicates Practice
A1: Week 7 — Finding and Removing Duplicates
A2: Look at Raw Customer Data closely. Some feedback entries are duplicates — same customer, same product, same feedback text, submitted twice. Find them BEFORE using Excel's Remove Duplicates tool, so you understand what it's actually removing.
A4: TASK 1 — Flag Duplicates with a Formula FIRST
A5: Before deleting anything, use COUNTIFS to flag which rows are duplicates based on Customer Name + Product. This protects you from deleting something that only LOOKS like a duplicate.
A6: Entry ID | B6: Customer + Product Check | C6: Your COUNTIFS Formula | D6: Duplicate?
A7: ='Raw Customer Data'!A4 -> FB-001 | B7: =TRIM('Raw Customer Data'!B4)&" - "&'Raw Customer Data'!G4 -> James Wilson - iPhone 15 | C7: COUNTIFS('Raw Customer Data'!B4:B23,'Raw Customer Data'!B4,'Raw Customer Data'!E4:E23,'Raw Customer Data'!E4) | D7: Yes
A8: ='Raw Customer Data'!A5 -> FB-002 | B8: =TRIM('Raw Customer Data'!B5)&" - "&'Raw Customer Data'!G5 -> Sarah Connor - Nike Hoodie | C8: COUNTIFS('Raw Customer Data'!B4:B23,'Raw Customer Data'!B5,'Raw Customer Data'!E4:E23,'Raw Customer Data'!E5) | D8: No
A9: ='Raw Customer Data'!A6 -> FB-003 | B9: =TRIM('Raw Customer Data'!B6)&" - "&'Raw Customer Data'!G6 -> Mike Johnson - Dyson Vacuum | C9: COUNTIFS('Raw Customer Data'!B4:B23,'Raw Customer Data'!B6,'Raw Customer Data'!E4:E23,'Raw Customer Data'!E6) | D9: Yes
A10: ='Raw Customer Data'!A7 -> FB-004 | B10: =TRIM('Raw Customer Data'!B7)&" - "&'Raw Customer Data'!G7 -> Emily Davis - Fenty Foundation | C10: COUNTIFS('Raw Customer Data'!B4:B23,'Raw Customer Data'!B7,'Raw Customer Data'!E4:E23,'Raw Customer Data'!E7) | D10: No
A11: ='Raw Customer Data'!A8 -> FB-005 | B11: =TRIM('Raw Customer Data'!B8)&" - "&'Raw Customer Data'!G8 -> Robert Brown - Samsung TV | C11: COUNTIFS('Raw Customer Data'!B4:B23,'Raw Customer Data'!B4,'Raw Customer Data'!E4:E23,'Raw Customer Data'!E4) | D11: Yes
A13: TASK 2 — Use Excel's Built-In Remove Duplicates Tool
A14: Step 1: Select your cleaned data range (once Tasks 1-5 in Cleaning Workspace are complete).
A15: Step 2: Data tab → Remove Duplicates.
A16: Step 3: Excel asks which columns to check. Tick Customer Name and Product Name — NOT Entry ID, since Entry ID is always unique even for duplicate feedback.
A17: Step 4: Click OK. Excel tells you how many duplicate rows were found and removed.
A18: Step 5: Compare this count to what your COUNTIFS formula predicted in Task 1. Do they match?
A19: WHY CHECK FIRST INSTEAD OF JUST CLICKING REMOVE DUPLICATES
A20: Remove Duplicates permanently deletes rows — there is no formula trail showing what was removed or why.
A21: If two customers happen to share a name but bought different products, checking the WRONG columns could delete a real, unique entry.
A22: A COUNTIFS flag first lets you SEE every duplicate before committing to deletion — this is the audit step AI would skip if you just told it 'remove duplicates'.

Sheet Orbitex Callback
A1: Orbitex Callback — Revisiting Week 2 With Text Functions
A2: In Week 2, city and category inconsistencies (nrth, NORTH, north) were caught using IF and COUNTIF against an allowed list. That found the problem. It did not FIX it. Text functions fix it.
A4: Then (Week 2) | B4: Now (Week 7) | C4: The Task
A5: Flag 'nrth' as Invalid, then manually retype it as 'North' in every row | B5: =PROPER(TRIM(city_cell)) fixes spacing and casing across every row instantly | C5: Standardizing inconsistent city names
A6: Flag mixed case categories as Invalid, no automatic fix | B6: =UPPER(category_cell) or PROPER() standardizes every category in one formula, dragged down | C6: Standardizing inconsistent category names
A7: No way to separate combined fields — data stayed messy | B7: =LEFT(), =MID(), =FIND() split combined fields into clean separate columns | C7: Splitting Region-Store Code into two usable columns
A9: Week 2 taught you to FIND problems. Week 7 taught you to FIX them without retyping a single cell by hand.

Sheet AI Audit
A1: Week 7 — AI Audit Log
A2: Give each cleaning task to AI first. Record the exact formula it produced and check it against the actual result before marking correct.
A4: AUDIT 1 — Name cleaning (TRIM + PROPER)
A5: Task given to AI | B5: Name cleaning (TRIM + PROPER)
A6: Exact formula/action AI produced | B6: PROPER(TRIM(A2))
A7: Was AI correct? Yes / No / Partially | B7: Yes
A8: What was wrong or missing | B8: nothing
A9: Error type: Wrong position number / Wrong function choice / Assumed column / Other | B9: nothing
A10: How I caught it | B10: comparing it to mine
A11: What this reveals about AI limitations in text cleaning | B11: nothing
A13: AUDIT 2 — Splitting Region-Store Code with FIND + LEFT/MID
A14: Task given to AI | B14: Splitting Region-Store Code with FIND + LEFT/MID
A15: Exact formula/action AI produced | B15: LEFT(A2,FIND(" ",A2)-1)
A16: Was AI correct? Yes / No / Partially | B16: Yes
A17: What was wrong or missing | B17: nothing was wrong or missing instead of using FIND and LEFT separately ai used FIND inside the LEFT and applied mathematical logical on num_chars condition in LEFT
A18: Error type: Wrong position number / Wrong function choice / Assumed column / Other | B18: Formula implementation logic not wrong but different
A19: How I caught it | B19: comparing to my logic and understading the logic and purpose behind -1 in formula
A20: What this reveals about AI limitations in text cleaning | B20: It shows that ai can do work even smarter with mathematics since it is mostly based on it. Mathematics is the logic of ai
A22: AUDIT 3 — Splitting Product Code and Name
A23: Task given to AI | B23: Splitting Product Code and Name
A24: Exact formula/action AI produced | B24: ai used LEFT(A2,FIND(" ",A2)-1) to split the product code and used MID(A2,FIND(" ",A2)+1,LEN(A2)) to split product name
A25: Was AI correct? Yes / No / Partially | B25: yes
A26: What was wrong or missing | B26: Nothing was wrong ai just used FIND inside the LEFT and for LEFT formula's num_chars condition it used LEN and reffered to the product code and name combined cell whereas I used 99 as we need till the end of characters of the product name and there was nothing else in the last except the product name
A27: Error type: Wrong position number / Wrong function choice / Assumed column / Other | B27: Formula implementation logic not wrong but different
A28: How I caught it | B28: Realizing the purpose of LEN in MID
A29: What this reveals about AI limitations in text cleaning | B29: It shows that ai can do work even smarter with mathematics since it is mostly based on it. Mathematics is the logic of ai
A31: AUDIT 4 — Phone number standardization with SUBSTITUTE
A32: Task given to AI | B32: Phone number standardization with SUBSTITUTE
A33: Exact formula/action AI produced | B33: ai used SUBSTITUTE(SUBSTITUTE(SUBSTITUTE(SUBSTITUTE(SUBSTITUTE(Sheet1!D2,".",""),"-","")," ",""),"(",""),")","") to remove every separater and it used IFERROR(TEXT(VALUE(B2),"000-000-0000"),"") to standardize the phone number
A34: Was AI correct? Yes / No / Partially | B34: yes
A35: What was wrong or missing | B35: Nothing ai just used nasted SUBSTITUTE like me and used TEXT and VALUE inside the IFERROR formula to to standardize every phone number which i don't know yet
A36: Error type: Wrong position number / Wrong function choice / Assumed column / Other | B36: Nothing was wrong in SUBSTITUTE and I don't know about standadizing since I don't know the functions ai used in IFERROR formula
A37: How I caught it | B37: comparing it to mine
A38: What this reveals about AI limitations in text cleaning | B38: Nothing
A40: AUDIT 5 — Ask AI to just 'remove duplicates' with no further instruction. Did it check the right columns, or assume?
A41: Task given to AI | B41: remove duplicates
A42: Exact formula/action AI produced | B42: ai removed the duplicate rows and returned unique values
A43: Was AI correct? Yes / No / Partially | B43: yes
A44: What was wrong or missing | B44: Nothing
A45: Error type: Wrong position number / Wrong function choice / Assumed column / Other | B45: Nothing
...
