Workbook
Name Slicer_Customer_Segment: #N/A
Name Slicer_Customer_Segment1: #N/A
Name Slicer_Month2: #N/A
Name Slicer_Product: #N/A
Name Slicer_Product_Category: #N/A
Name Slicer_Region: #N/A
Name Slicer_Sales_Rep: #N/A

Sheet Sheet1
A3: Row Labels | B3: Sum of Revenue ($)
A4: Sports | B4: 47108
A5: Electronics | B5: 38960
A6: Home Appliances | B6: 19170
A7: Clothing | B7: 6694
A8: Beauty | B8: 3291
A9: Grand Total | B9: 115223
A11: Row Labels | B11: Sum of Revenue ($)
A12: Sports | B12: 47108
A13: Electronics | B13: 38960
A14: Home Appliances | B14: 19170
A15: Clothing | B15: 6694
A16: Beauty | B16: 3291

Sheet Conditional Formatting
A1: NEXACORE RETAIL — Conditional Formatting Practice
A2: Apply each rule to the Sales Data sheet or your Pivot Table outputs. Conditional Formatting lives under the Home tab.
A4: CF1 — BASIC
A5: Task | B5: Highlight Top 10 Revenue Transactions
A6: Steps | B6: Select Revenue column in Sales Data. Home → Conditional Formatting → Top/Bottom Rules → Top 10 Items. Color: Green fill.
A7: Why | B7: Instantly shows which transactions drove the most revenue. No formula needed.
A8: Answer this | B8: What percentage of total revenue do the top 10 transactions represent?
A9: Insight | B9: The top 10 transaction represent 82.5087005198615% of total revenue. Process: apply conditional formating to the revenue column turn top 10 cells green then filter by colour get the sum of top 10 revenue transaction remove the filter get the sum of revenue then devide sum of top 10 revenue transactions with sum of revenue then multiply it with 100 you get the percentage of top 10 revenue transactions to the sum of revenue.
A11: CF2 — BASIC
A12: Task | B12: Highlight Bottom 10 Revenue Transactions
A13: Steps | B13: Same column. Bottom 10 Items. Color: Red fill.
A14: Why | B14: Identifies your lowest value transactions. Are they concentrated in one category or region?
A15: Answer this | B15: Are the bottom 10 all from one region or spread across all four?
A16: Insight | B16: The bottom 10 transactions are spread across all four regions.
A18: CF3 — INTERMEDIATE
A19: Task | B19: Color Scale on Revenue Column
A20: Steps | B20: Select Revenue column. Conditional Formatting → Color Scales → Green-Yellow-Red. Green = high, Red = low.
A21: Why | B21: Creates a visual heat map of transaction values. Pattern recognition without reading numbers.
A22: Answer this | B22: Which rows have the most green? Which have the most red? What do they have in common?
A23: Insight | B23: Most green only has premium category, most red has only standard category and they all are in february there is a pattern noticed some categories returning most red in a specific month. Conclusion: some categories are not performing in specific months and some are only performing in specific months.
A25: CF4 — INTERMEDIATE
A26: Task | B26: Data Bars on Units Sold Column
A27: Steps | B27: Select Units Sold column. Conditional Formatting → Data Bars → Blue fill.
A28: Why | B28: Each cell shows a bar proportional to its value. Instantly see quantity distribution.
A29: Answer this | B29: Which product categories consistently have longer bars?
A30: Insight | B30: Standard has more consistent longer bars.
A32: CF5 — INTERMEDIATE
A33: Task | B33: Highlight All Electronics Rows
A34: Steps | B34: Select entire dataset rows 4 to 203. Conditional Formatting → New Rule → Use formula. Formula: =$F4='Electronics'. Color: Light blue fill.
A35: Why | B35: Highlights every Electronics transaction across the entire dataset at once.
A36: Answer this | B36: How does the Electronics row density compare visually to other categories?
A37: Insight | B37: Electronics row is as dense as other categories there is one electronics row after every 4 rows.
A39: CF6 — ADVANCED
A40: Task | B40: Flag Revenue Below 200 as Red
A41: Steps | B41: Select Revenue column. New Rule → Format cells that contain → Cell Value less than 200. Red fill.
A42: Why | B42: Immediately identifies low value transactions that may not justify shipping or service costs.
A43: Answer this | B43: How many transactions fall below 200? Which category has the most?
A44: Insight | B44: There are 198 transactions those fall below 200 every 66 transactions fall below 200 in every category.
A46: CF7 — ADVANCED
A47: Task | B47: Flag Premium Segment Rows in Gold
...

Sheet Slicers Guide
A1: NEXACORE RETAIL — Slicers Practice
A2: Slicers are visual filters connected to Pivot Tables. They let anyone filter data by clicking buttons instead of using dropdowns.
A4: HOW TO ADD A SLICER
A5: Step 1: Create a Pivot Table first. Slicers attach to Pivot Tables.
A6: Step 2: Click anywhere inside the Pivot Table to select it.
A7: Step 3: Go to PivotTable Analyze tab (appears when Pivot Table is selected).
A8: Step 4: Click Insert Slicer.
A9: Step 5: Tick the fields you want as slicer buttons — Region, Category, Month, Sales Rep.
A10: Step 6: Click OK. Slicers appear as floating panels on your sheet.
A11: Step 7: Click any button on the slicer to filter your Pivot Table instantly.
A12: Step 8: Hold Ctrl and click multiple buttons to select more than one filter at once.
A13: Step 9: Click the X button on the slicer to clear all filters.
... A18: Why this matters: Slicers make cross-filtering instant. This question needs two slicers working together.
A19: Insight | B19: Electronics revenue is $38,960 in all regions and $81,40 in south region, electronics in south performed less than north east and west.
A21: ST2 — Add Month and Sales Rep slicers to PT3
A22: Question: Filter to January only. Who was the top performer in January? Now switch to March. Did the ranking change?
A23: Why this matters: Monthly slicer on a rep ranking shows performance consistency vs one-off peaks.
A24: Insight | B24: James Wilson was still the top performer in january but in march Mike Johnson took over.
A26: ST3 — Add Customer Segment slicer to PT1
A27: Question: Filter to Premium segment only. Which region has the most Premium customers? How does this compare to Budget segment by region?
A28: Why this matters: Segment slicer reveals whether regions attract different customer types.
A29: Insight | B29: North has the most premium customers, north also has the most budget customers and budget has gained most revenue in north whereas premium has gained less revenue in north than budget.
A31: ST4 — Connect one slicer to multiple Pivot Tables
A32: Question: Create PT1 and PT2 on the same sheet. Add a Region slicer. Right click the slicer and select Report Connections. Connect it to both pivot tables. Now filtering by region updates both charts simultaneously.
A33: Why this matters: This is how real dashboards work. One filter controls multiple visualizations.
A34: Insight | B34: Filtering by region updates the both charts according to filter.
A36: ST5 — Add Timeline slicer for Month filtering
A37: Question: Click Pivot Table. PivotTable Analyze → Insert Timeline → Select Date field. A timeline bar appears. Drag to select specific months. This is more visual than a standard slicer for date filtering.
A38: Why this matters: Timeline slicers are specifically for date fields. More intuitive for time-based analysis.
A39: Insight | B39: Timeline slicer didn't work I tried both ways to solve it that you told me but it didn't work so since you told me if it doesn't work leave it I'm leaving it.

Sheet Pivot Table Tasks
A1: NEXACORE RETAIL — Pivot Table Practice Tasks
A2: Create each Pivot Table from the Sales Data sheet. Insert → PivotTable → Select Sales Data range → Place in a new sheet or below each task.
A4: PT1 — BASIC
A5: Pivot Name | B5: Revenue by Region
A6: Setup | B6: Rows: Region | Values: Sum of Revenue
A7: Business Q | B7: Which region generates the most revenue? Is there a significant gap between top and bottom
A8: Business Insight | B8: North has genrated most revenue by hitting $39,435 in revenue missing our second top target $40,000 by 1.4% in revenue by $565, whereas south and west are performing significantly low not even close to our third top target $30,00 and even missing second target $20,000 by 7.18% - 6.83% in revenue by $1,437 - $1,366. Conclusion: there is significant need to analyse south and west's perfomance in detail and form a strategy according analysis
A9: Chart Type | B9: Bar Chart — sorted highest to lowest | N9: 115223
A11: PT2 — BASIC
A12: Pivot Name | B12: Revenue by Product Category
A13: Setup | B13: Rows: Category | Values: Sum of Revenue
A14: Business Q | B14: Which product category drives the most revenue? Which is consistently underperforming?
A15: Business Insight | B15: Sports has gained the most significant revenue by achieving $47,108 in revenue whereas Beauty is Significantly underperforming by just $3,291 in revenue even gaining 50.83% less revenue from the second most least performing category. Conclusion: Beauty category needs further in detail analysis, analysing its performance per region if any specific region is underperforming we would need to either reform the category according to that region demographics or withdraw the category from that region if the entire category is underperfoming in every region we really need to reform the category and form strategies that can give minimum 60% - 70% growth posibility per region.
A16: Chart Type | B16: Pie Chart — show percentage share
A18: PT3 — INTERMEDIATE
A19: Pivot Name | B19: Revenue by Sales Rep
A20: Setup | B20: Rows: Sales Rep | Values: Sum of Revenue | Sort: Largest to Smallest
A21: Business Q | B21: Who are the top 3 performers? Who are the bottom 3? What is the gap between them?
A22: Business Insight | B22: James Wilson, David Lee, Joshua Jackson are the top 3 performers on very top there is James Wilson with an exellent performance with $21,504 in revenue by sales rep crossing fourth target $20,000 and completing fifth target $25,000 by 30.08% then there is David Lee with $20,626 in revenue crossing fourth target and completing fifth target by 12.52% then there is Joshua Jackson crossing second target $10,000 by completing $10,997 in revenue and completing third target $15,000 by 19.94%
A23: Chart Type | B23: Bar Chart — sorted to show ranking clearly
A25: PT4 — INTERMEDIATE
A26: Pivot Name | B26: Monthly Revenue Trend
A27: Setup | B27: Rows: Month | Values: Sum of Revenue
A28: Business Q | B28: Is revenue growing month over month? Which month had the sharpest drop or spike?
A29: Business Insight | B29: Revenue Trend all time is down right now means revenue is decreasing over the time, january had all time high with $42,130 in revenue in feburary revenue dropped by 49.91% considering the most sharpest drop of all time dropping $21,029 in revenue, feburary to march revenue trend was also down dropping by 11.53% from previous month and 55.69% from all time high april got the most lowest point with $7,129 in revenue dropping by 61.80% from previous month considering the all time low whereas in may the revenue is increased by 58.62% with $17,230 in revenue considering the sharpest spike yet, then june went down again closing $8,967 in revenue by 47.96%. Conclusion: The january has the sharpest drop ending on april constantly revenue dropping by 83.07% then april has the most sharpest spike yet but not strong. Seasonal analysis is needed in detail and a strong strategy according to the seasonal analysis.
A30: Chart Type | B30: Line Chart — shows trend direction
A32: PT5 — INTERMEDIATE
A33: Pivot Name | B33: Revenue by Region AND Category
A34: Setup | B34: Rows: Region | Columns: Category | Values: Sum of Revenue
A35: Business Q | B35: Which category performs best in each region? Are there regional strengths and weaknesses?
A36: Business Insight | B36: Sports has performed best in north and east and Electronics in south and west. south and west are weakend as compare to north and east whereas beauty is underperforming in every region in north and east sports is most high performing one but in south and west it is second highest performer but performing lower than the north and east region by around 70.10% electronics performing most highest in south and west region but as like sports lower from the north and east. conclusion: north and east needs detailed category analysis with demographics and a strategy to increase categories performence like sports, home appliances, clothing, beauty and beauty specifically needs a strong strategy and in detail products analysis in beauty in some case there is a significant posibility to withdraw or completely reform the category from every region.
A37: Chart Type | B37: Heatmap using Conditional Formatting on the pivot output
A39: PT6 — ADVANCED
A40: Pivot Name | B40: Revenue by Customer Segment by Month
A41: Setup | B41: Rows: Month | Columns: Customer Segment | Values: Sum of Revenue
A42: Business Q | B42: Is Premium segment growing faster than Budget? Which segment is most consistent?
A43: Business Insight | B43: Premium is significantly growing faster than budget. Standard is significantly more consistant than premium and budget customers prefers standard more than premium and budget, there is also a similar pattern noticed in standard and budget in january standard and budget both are dead. conclusion: customer segment needs seasonal analysis in detail.
A44: Chart Type | B44: Line Chart with 3 lines — one per segment
A46: PT7 — ADVANCED
A47: Pivot Name | B47: Average Order Value by Sales Rep and Region
...

Sheet KPI Definition
A1: NEXACORE RETAIL — KPI Definition Exercise
A2: AI cannot define your KPIs for you. This is your job. Read the business context below and define which metrics matter — and why.
A4: BUSINESS CONTEXT
A5: Nexacore Retail operates across 4 regions in the US — North, South, East, West.
A6: They sell 5 product categories: Electronics, Clothing, Home Appliances, Beauty, and Sports.
A7: They have 12 sales reps each assigned to a specific region.
A8: They serve 3 customer segments: Premium, Standard, and Budget.
A9: The CEO wants a monthly performance dashboard and needs to know which numbers to watch.
A10: The Sales Director wants to know which reps are underperforming before the next quarter.
A11: The Product Manager wants to know which categories are growing and which are declining.
A12: The Finance team wants to track revenue targets and margin performance.
A14: YOUR KPI DEFINITIONS — Fill in every yellow cell. No AI. Your own thinking.
A15: KPI Name | B15: What it measures | C15: Why it matters to the business | D15: Which stakeholder needs it | E15: How to calculate it | F15: Good or bad if it increases?
A16: Total Revenue | B16: It measures the overall revenue across 6 months overall revenue across all categories and all regions inshort this indicates overall revenue growth of Nexacore. | C16: every business has their target or goal to achieve it defines if business has reached the goal or not if yes then how much it has scaled more than goal if not then how it has missed the target or goal by percentage or target revenue either it is too low it needs strategy reform and in detail analysis it can also matters to finance department to calculate share in revenue for each shareholder inshort it can matter in varies ways some of which i have mentioned above. Nexacore's Total revenue is $115,223. Whether it is good or not Whether it matters or not this can be decided to Nexacore's goal which is not provided. a general conclusion that Nexacore is opperating across four regions and having $115,223 in total revenue across 6 months looks very low. | D16: Investor needs to have idea of Total revenue of business so that he can look over how his investment is doing or he can scale or increase his investment more if anyone who is intereseted in investing he also needs this he will get know is it safe to invest in business and according to business growth he will get idea what amount of investment will be fine, CEO needs it to look over how much business has gained then he will take discisions according to it, and finance team needs it to maintain a record of business return. | E16: sum the entire revenue of business over past months. | F16: it is good if it increases, gradually very less but in some cases revenue increasing in unnatural way could be because of some suspecious causes. | H16: 115223
A17: Revenue per Sales Rep | B17: It measures how good a sales rep has performed, it trackes sales rep performance. | C17: it can lead the business to focus on high performing sales rep then further business can form strategies and take some dicsions those will cause business growth like focusing to maintain a good relation with those high performing sales rep, appreciet them with anything to increase their confidence and making their bond with business more stronger and organizing training sessions which high sales rep would lead to increase performance of more sales rep and assigning them the tasks that a high performer would do best. Revenue per sales rep of Nexacore matters in a way that high sales rep needs to be appreciate and assigned with the tasks those needs high sales rep and they can lead the trainings for underperforming sales rep, underperforming sales rep can be highlighted and business can focus on them specifically to make their performance more good by organizing training sessions for them and a bit harsh but if a sales rep is constantly underperforming and not growing business can withdraw them. | D17: CEO needs this it will help him to assign and take discisions for sales rep according to their performance like assigning tasks, assigning regions those needs more progress, Sales director needs this, HR needs this to having an idea of quality of bond and relation he needs to maintain with high sales rep in varies ways like giving promotion, negotiating with them, granting leaves and a bit about office politics and matters also, Finance team needs this to track high sales rep performance and granting salary promotions or bonus if cariterias are decided. | E17: setting up pivot table adding sales rep in row and sum of revenue in values | F17: it is good if it increases, but as like revenue unnatural spike or growth can because of some suspecious things like faking orders or spaming, very less but a real thing.
A18: Top Performing Region | B18: it measures revenue by region | C18: north has performed highest in regions by gaining $39,435 in revenue whereas south and west has collectively gained $37,197 in revenue, south and west really needs demographic analysis in detail and regional analysis also. | D18: CEO needs this for taking discision about regional analysis and having an idea of how each region is performing, Product Research team needs this to research on regional demographics and only sorting top products or reforming products | E18: setting up pivot table adding region in row and sum of revenue in values | F18: it is really good if it increases specially for south and west, north and east is already scaled more if north and east will increase it will be also but it will lead the business to take serious discision about scaling business in that region.
A19: Category Return Rate | B19: it measures revenue gained by each category. | C19: Sports has gained the most significant revenue by achieving $47,108 in revenue whereas Beauty is Significantly underperforming by just $3,291 in revenue even gaining 50.83% less revenue from the second most least performing category. Conclusion: Beauty category needs further in detail analysis, analysing its performance per region if any specific region is underperforming we would need to either reform the category according to that region demographics or withdraw the category from that region if the entire category is underperfoming in every region we really need to reform the category and form strategies that can give minimum 60% - 70% growth posibility per region. | D19: Product Research team needs this and CEO also needs this. | E19: setting up pivot table adding category in row and sum of revenue in values | F19: it is good and necessary if it increases
A20: Average Order Value | B20: it measures average of sum of revenue across past months | C20: average order value of Nexacore is 19203.83 we should look for what our compatitor's average order value look like then if we wanna grow we should take further steps to strategis reform the company to increase its performance. I guess we don't have anything in average order value to discuss that much in deep about from my perspective its just a matrics for Nexacore yet. | D20: CEO needs this and Finance department needs this. | E20: setting up pivot table adding month in rows and sum of revenue in values then taking average of sum of revenue. | F20: it can be good in some cases and in some cases can't because if average is increasing can mean that every month revenue is increasing which is good the average can also increase when just some of months are doing well and other are decreasing in revenue expanded overlook matters. | H20: 19203.833
A21: Month over Month Growth | B21: it measures other performance of Nexacore by the revenue growing or decreasing month over month comparing each month's revenue with past months | C21: we had a solid growth in revenue in january gaining $42,130 in revenue in feburary it dropped by 49.91% in revenue $21,029 considering the second most sharpest drop in the entire six months then again in march revenue dropped by 11.53% from the past month and 55.69% from the all time high also considering the slightest drop in the six months from feburary to march then in april the sharpest drop happened gaining $7,129 in revenue dropping by 61.80% from the past month considering the most sharpest drop in the entire six months and 83.07% from the all time high business reaching its lowest point the all time low hypothetically considering the dangerous zone in any business may gained $17,230 in revenue growth happening by 58.62% from the last month considering the sharpest apike in the entire six months june gained $8,967 in revenue dropping by 47.76%. conclusion: the down trend started from january happening in february and continues for the rest of five months march had slightest drop after march the fluctuation started analysis not clearly indicating the reason. the seasonal analysis is required in detail with demographics and regional analyisis. | D21: CEO needs this to direct the teams and take discisions, Analysis team needs this if there is a saperate one if not then Product Research team needs this to analyse and research for the products according to the result of seasonal analysis and regional analysis and demographics, Finance department needs this to calculate risks and maintain an accountability bounderies. | E21: setting up pivot table adding month in rows and sum of revenue in values | F21: it is good if it increases and it really needs to be increased but at some point such as at the mid growth or in dangerous zone business needs to focus more on maintaining a middle flow as rappid action then focus on growth over all conclusion the increase in growth is good.
A22: Revenue by Customer Segment | B22: It measure how much revenue each customer segment has gained in the past months | C22: Premium gained $42,130 in january and dropped to the $0 in februay and march dead for the complete two months constantly gaining 16.92% of its all time high then again gaining $0 in may and june sharpest drop happening in premium in the all customer segment gaining $49,259 in revenue in the entire six months and four months of dead, standard gained $0 in revenue in january then gaining $21,101 in revenue in february then again gaining $0 in march and april in may standard gained $17,230 and $0 in june standard gaining $38,331 in revenue in entire six months and four months of dead, budget gaining $0 in january and february then gaining $18,666 in revenue in march then again gaining $0 in april and may in june budget gained $8,967 in revenue budget gaining $27,633 in revenue in entire six months and four months of dead. conclusion: premium gained the most revenue than the standard and budget sharpest drop happening february revenue dropping from $42,130 to $0 somehow shows the customer interest instantly dropping in february looking at customer's behaivour and prefrences 97% of times customer choose premium for gifting, celebration, event or occasion the possible cause of premium gaining most revenue in january can be any event or occasion most possiblly christmas or new year but both happens in december so the event possiblity can't be fully applied on it so we move towards the other possiblities such as consistency of premium depends on any specific category that is seasonal but Nexacore's premium is spread across every category in january so this possiblity is also invalid seasonal analysis in detail is needed for more clarity and increasing premium performance across six months but from current analysis business can introduce more offers and new products in january and april as in these two months premium stands in high demand, standard can be focused on integration in february and may and budget can be focused on modification and integration in march and june, in january business needs to focus on premium item's strategy such as introducing offers, refining premium products, introducing new categories or products in premium sagment, ensuring premium item's stock availblity in advance for january in february business should focus on standard in march on budget in april on premium in may on standard and in june on budget, there is a pattern noticed every sagment stands in demand after two months but this finding doesn't indicate anything specific or valuable. | D22: CEO needs this to direct the teams and take discisions, Analysis team needs this if there is a saperate one, Product Research team needs this improve categories and products as per sagment by month and form strategies. | E22: setting up pivot table adding customer segment in rows and sum of revenue in values | F22: it is good if it increases but there are some levels if budget increases it is good if standard increases it is better if premium increases it is best.
A23: Underperforming Products | B23: It measures the products gaining less revenue than the middle range in the past months | C23: Most of the underperforming products are from beauty and clothing category product research team needs to research and analyse why these products are underperforming and refine and improve the products if no solid reason found then business can withdraw these products which will result in massive investment saving and then business should focus on introducing new products either alternet of these or complete but after a proper market and customer demographics research. | D23: CEO needs this to direct the teams and take discisions, Product Research team needs this to start inquiry in detail and improve the products performance. | E23: setting up pivot table adding product in rows and sum of revenue in values then sorting revenue large to small then taking median value of revenue to get middle value then applying conditional formatting on revenue adding custom formula the cell less than median value then appying red colour and then filtering by colour. | F23: It is good if it increases.
A24: Category Revenue by percent | B24: It measures how much percent of business revenue come from each category | C24: Most of the business revenue comes from sports by 40.88%, electronics gained revenue by 33.81% of business sports and electronics drives the most revenue of business focusing and managing these both categories is really important such as check-in-balance, stock availblity and product quality any affect on any of category from these would result in business performance. | D24: CEO needs this to have a sense of future risk possiblities, Product Research team needs this to improve these categories more it will direct result in revenue growth. | E24: adding slicer to Revenue by category chart then selecting each category to see the most driven revenue then taking percentage of them. | F24: It is good if it increases.
A25: Define your own KPI here | B25: Write your answer here | C25: Write your answer here | D25: Write your answer here | E25: Write your answer here | F25: Write your answer here
A27: REMEMBER: A KPI is only useful if it leads to a decision. If knowing this number does not change what the business does — it is not a KPI, it is just a metric.

Sheet Sales Data
A1: NEXACORE RETAIL — Sales Transaction Data (Clean — 200 Rows)
A2: This is your Week 4 dataset. Use it to build Pivot Tables, apply Conditional Formatting, add Slicers, define KPIs, and build your Sales Dashboard.
A3: Transaction ID | B3: Date | C3: Month | D3: Sales Rep | E3: Region | F3: Product Category | G3: Product | H3: Units Sold | I3: Unit Price ($) | J3: Revenue ($) | K3: Customer Segment
A4: TXN-001 | B4: 46055 | C4: February | D4: Robert Brown | E4: South | F4: Clothing | G4: Levi Jeans | H4: 1 | I4: 79 | J4: 79 | K4: Standard | L4: =AVERAGE(J4:J203) -> 576.115
A5: TXN-002 | B5: 46084 | C5: March | D5: Chris Anderson | E5: East | F5: Home Appliances | G5: Instant Pot | H5: 2 | I5: 129 | J5: 258 | K5: Budget
A6: TXN-003 | B6: 46116 | C6: April | D6: Amanda Thomas | E6: West | F6: Beauty | G6: Tatcha Serum | H6: 1 | I6: 88 | J6: 88 | K6: Premium | L6: =SUM(J4:J203) -> 115223
A7: TXN-004 | B7: 46147 | C7: May | D7: Sarah Connor | E7: North | F7: Sports | G7: TRX System | H7: 3 | I7: 179 | J7: 537 | K7: Standard
A8: TXN-005 | B8: 46179 | C8: June | D8: Lisa Martinez | E8: South | F8: Electronics | G8: Sony Headphones | H8: 1 | I8: 349 | J8: 349 | K8: Budget
A9: TXN-006 | B9: 46029 | C9: January | D9: David Lee | E9: East | F9: Clothing | G9: Nike Hoodie | H9: 2 | I9: 89 | J9: 178 | K9: Premium
A10: TXN-007 | B10: 46061 | C10: February | D10: Joshua Jackson | E10: West | F10: Home Appliances | G10: KitchenAid Mixer | H10: 1 | I10: 399 | J10: 399 | K10: Standard
A11: TXN-008 | B11: 46090 | C11: March | D11: Mike Johnson | E11: North | F11: Beauty | G11: MAC Lipstick | H11: 1 | I11: 24 | J11: 24 | K11: Budget
A12: TXN-009 | B12: 46122 | C12: April | D12: Emily Davis | E12: South | F12: Sports | G12: Yeti Cooler | H12: 2 | I12: 249 | J12: 498 | K12: Premium
A13: TXN-010 | B13: 46153 | C13: May | D13: Jennifer Taylor | E13: East | F13: Electronics | G13: Dell Laptop | H13: 1 | I13: 1099 | J13: 1099 | K13: Standard
A14: TXN-011 | B14: 46185 | C14: June | D14: Ashley White | E14: West | F14: Clothing | G14: Ralph Lauren Polo | H14: 1 | I14: 95 | J14: 95 | K14: Budget
A15: TXN-012 | B15: 46035 | C15: January | D15: James Wilson | E15: North | F15: Home Appliances | G15: Dyson Vacuum | H15: 2 | I15: 549 | J15: 1098 | K15: Premium
A16: TXN-013 | B16: 46067 | C16: February | D16: Robert Brown | E16: South | F16: Beauty | G16: Dior Perfume | H16: 1 | I16: 125 | J16: 125 | K16: Standard
A17: TXN-014 | B17: 46096 | C17: March | D17: Chris Anderson | E17: East | F17: Sports | G17: Garmin Watch | H17: 3 | I17: 299 | J17: 897 | K17: Budget
A18: TXN-015 | B18: 46128 | C18: April | D18: Amanda Thomas | E18: West | F18: Electronics | G18: AirPods Pro | H18: 1 | I18: 249 | J18: 249 | K18: Premium
... A203: TXN-200 | B203: 46086 | C203: March | D203: Mike Johnson | E203: North | F203: Electronics | G203: Samsung TV | H203: 1 | I203: 1299 | J203: 1299 | K203: Budget
I204: Total Revenue | J204: =SUM(J4:J203) -> 115223

Sheet Dashboard Charts

Sheet Dashboard Pivot tables
A1: total revenue | B1: top region | E1: total units sold | G1: top sales rep | J1: sales rep table for top sales rep | N1: Revenue by region filter with filter for top region
A2: =SUM('Sales Data'!J4:J203) -> 115223 | B2: south | C2: =SUM(O3:O52) -> 18634 | E2: =SUM('Sales Data'!H4:H203) -> 300 | G2: maximum revenue | H2: =MAX(L2:L13) -> 21504 | J2: {=_xlfn.UNIQUE('Sales Data'!D6:D202,FALSE,FALSE)} -> Amanda Thomas | L2: =SUMIF('Sales Data'!$D$6:$J$202,J2,'Sales Data'!$J$6:$J$202) -> 3484 | O2: south | P2: north | Q2: east | R2: west | U2: Row Labels | V2: Sum of Units Sold | W2: Row Labels | X2: Sum of Revenue ($)
A3: =SUM(C2:C5) -> 115223 | B3: north | C3: =SUM(P3:P52) -> 39435 | G3: top sales rep | H3: =INDEX(J2:K13,MATCH(H2,L2:L13,0),1) -> James Wilson | J3: Sarah Connor | L3: =SUMIF('Sales Data'!$D$6:$J$202,J3,'Sales Data'!$J$6:$J$202) -> 8514 | O3: 79 | P3: 537 | Q3: 258 | R3: 88 | U3: Electronics | V3: 39 | W3: East | X3: 38591
B4: east | C4: =SUM(Q3:Q52) -> 38591 | D4: Top KPI boxes | J4: Lisa Martinez | L4: =SUMIF('Sales Data'!$D$6:$J$202,J4,'Sales Data'!$J$6:$J$202) -> 4885 | O4: 349 | P4: 24 | Q4: 178 | R4: 399 | U4: Beauty | V4: 40 | W4: North | X4: 38136
B5: west | C5: =SUM(R3:R52) -> 18563 | J5: David Lee | L5: =SUMIF('Sales Data'!$D$6:$J$202,J5,'Sales Data'!$J$6:$J$202) -> 20626 | O5: 498 | P5: 1098 | Q5: 1099 | R5: 95 | U5: Home Appliances | V5: 60 | W5: South | X5: 18634
B6: maximum revenue | C6: =MAX(C2:C5) -> 39435 | J6: Joshua Jackson | L6: =SUMIF('Sales Data'!$D$6:$J$202,J6,'Sales Data'!$J$6:$J$202) -> 10997 | O6: 125 | P6: 360 | Q6: 897 | R6: 249 | U6: Clothing | V6: 60 | W6: West | X6: 18563
B7: top region | C7: =INDEX(B2:B5,MATCH(C6,C2:C5,0),1) -> north | J7: Mike Johnson | L7: =SUMIF('Sales Data'!$D$6:$J$202,J7,'Sales Data'!$J$6:$J$202) -> 8118 | O7: 549 | P7: 1299 | Q7: 42 | R7: 698 | U7: Sports | V7: 100 | W7: Grand Total | X7: 113924
J8: Emily Davis | L8: =SUMIF('Sales Data'!$D$6:$J$202,J8,'Sales Data'!$J$6:$J$202) -> 3645 | O8: 65 | P8: 4485 | Q8: 358 | R8: 38 | U8: Grand Total | V8: 299
J9: Jennifer Taylor | L9: =SUMIF('Sales Data'!$D$6:$J$202,J9,'Sales Data'!$J$6:$J$202) -> 8716 | O9: 1999 | P9: 185 | Q9: 220 | R9: 149
J10: Ashley White | L10: =SUMIF('Sales Data'!$D$6:$J$202,J10,'Sales Data'!$J$6:$J$202) -> 4082 | O10: 298 | P10: 258 | Q10: 999 | R10: 79
J11: James Wilson | L11: =SUMIF('Sales Data'!$D$6:$J$202,J11,'Sales Data'!$J$6:$J$202) -> 21504 | O11: 88 | P11: 178 | Q11: 537 | R11: 349 | U11: Row Labels | V11: Sum of Revenue ($)
J12: Robert Brown | L12: =SUMIF('Sales Data'!$D$6:$J$202,J12,'Sales Data'!$J$6:$J$202) -> 10025 | O12: 399 | P12: 1099 | Q12: 24 | R12: 498 | U12: David Lee | V12: 20626
H13: E | J13: Chris Anderson | L13: =SUMIF('Sales Data'!$D$6:$J$202,J13,'Sales Data'!$J$6:$J$202) -> 8991 | O13: 95 | P13: 897 | Q13: 1098 | R13: 125 | U13: James Wilson | V13: 21504
H14: N | O14: 249 | P14: 42 | Q14: 360 | R14: 549 | U14: Joshua Jackson | V14: 10997
H15: S | O15: 698 | P15: 358 | Q15: 1299 | R15: 65 | U15: Grand Total | V15: 53127
H16: W | O16: 38 | P16: 220 | Q16: 4485 | R16: 1999
O17: 149 | P17: 999 | Q17: 185 | R17: 298 | U17: Row Labels | V17: Sum of Revenue ($) | W17: Sales Rep | X17: Revenue
O18: 79 | P18: 537 | Q18: 258 | R18: 88 | U18: James Wilson | V18: 21504 | W18: James Wilson | X18: 21504
O19: 349 | P19: 24 | Q19: 178 | R19: 399 | U19: David Lee | V19: 20626 | W19: David Lee | X19: 20626
O20: 498 | P20: 1098 | Q20: 1099 | R20: 95 | U20: Joshua Jackson | V20: 10997 | W20: Joshua Jackson | X20: 10997
O21: 125 | P21: 360 | Q21: 897 | R21: 249 | U21: Robert Brown | V21: 10104 | W21: Ashley White | X21: 4082
O22: 549 | P22: 1299 | Q22: 42 | R22: 698 | U22: Chris Anderson | V22: 9249 | W22: Emily Davis | X22: 3645
O23: 65 | P23: 4485 | Q23: 358 | R23: 38 | U23: Jennifer Taylor | V23: 8716 | W23: Amanda Thomas | X23: 3484
O24: 1999 | P24: 185 | Q24: 220 | R24: 149 | U24: Sarah Connor | V24: 8514
O25: 298 | P25: 258 | Q25: 999 | R25: 79 | U25: Mike Johnson | V25: 8118
O26: 88 | P26: 178 | Q26: 537 | R26: 349 | U26: Lisa Martinez | V26: 4885
O27: 399 | P27: 1099 | Q27: 24 | R27: 498 | U27: Ashley White | V27: 4082
O28: 95 | P28: 897 | Q28: 1098 | R28: 125 | U28: Emily Davis | V28: 3645
O29: 249 | P29: 42 | Q29: 360 | R29: 549 | U29: Amanda Thomas | V29: 3484
O30: 698 | P30: 358 | Q30: 1299 | R30: 65 | U30: Grand Total | V30: 113924
O31: 38 | P31: 220 | Q31: 4485 | R31: 1999
O32: 149 | P32: 999 | Q32: 185 | R32: 298
O33: 79 | P33: 537 | Q33: 258 | R33: 88
O34: 349 | P34: 24 | Q34: 178 | R34: 399
O35: 498 | P35: 1098 | Q35: 1099 | R35: 95
O36: 125 | P36: 360 | Q36: 897 | R36: 249
O37: 549 | P37: 1299 | Q37: 42 | R37: 698
O38: 65 | P38: 4485 | Q38: 358 | R38: 38
O39: 1999 | P39: 185 | Q39: 220 | R39: 149
G40: Top Bottom Sales Rap performance | O40: 298 | P40: 258 | Q40: 999 | R40: 79
...

Sheet Dashboard
D1: N E X A C O R E RETAIL SALES ANALYSIS | V1: Total Revenue
V2: ='Dashboard Pivot tables'!A2 -> 115223
V3: Total Units Sold
V4: ='Dashboard Pivot tables'!E2 -> 300
V5: Top Sales Rep
V6: James Wilson
V7: Top Region
V8: South 18634
V9: North 39435
V10: East 38591
V11: West 18563
V12: Maximum Revenue 39435
V13: Top Region North
V14: Top Bottom Sales Rap Performance
V15: Sales Rep Revenue
V16: James Wilson 21504
... V21: Amanda Thomas 3484

Sheet Dashboard Layout Design

Sheet Dashboard Brief
A1: NEXACORE RETAIL — Sales Dashboard Mini Project Brief
A2: This is your Week 4 mini project. Build a complete executive Sales Dashboard that answers real business questions using Pivot Tables, Charts, Slicers, and Conditional Formatting.
A4: THE SCENARIO
A5: The CEO of Nexacore Retail has called a quarterly review meeting in 48 hours.
A6: She wants a single dashboard that tells her everything she needs to know about sales performance.
A7: She is not technical. She reads charts not tables. She makes decisions in under 30 seconds per slide.
A8: Your job is to build that dashboard — clean, clear, and immediately actionable.
A9: Every visual must answer a specific business question. No decorative charts.
A11: DASHBOARD REQUIREMENTS
A12: R1 — KPI Summary Row
A13: Task | B13: At the top of the dashboard show 4 KPI boxes: Total Revenue, Total Units Sold, Top Region, Top Sales Rep.
A14: Answers | B14: Use SUMIF, COUNTIF, INDEX MATCH, and MAX formulas — not Pivot Tables — for these numbers.
A15: Note | B15: This tests whether you can combine Week 3 and Week 4 skills together.
A17: R2 — Revenue by Region Chart
A18: Task | B18: Bar chart from PT1. Sorted highest to lowest. Color coded using Conditional Formatting.
A19: Answers | B19: Answers: Where is Nexacore strongest? Where is it weakest?
A20: Note | B20: Must have a clear title that states the business insight not just the data.
A22: R3 — Monthly Revenue Trend Chart
A23: Task | B23: Line chart from PT4. Show 6 months. Add a trendline.
A24: Answers | B24: Answers: Is the business growing or declining? Where was the sharpest change?
A25: Note | B25: The CEO must be able to see the direction in under 5 seconds.
A27: R4 — Category Performance Chart
A28: Task | B28: Bar or Pie chart from PT2. Show revenue AND units side by side or in separate charts.
A29: Answers | B29: Answers: Which category should get more investment? Which is underperforming?
A30: Note | B30: High units but low revenue means low price point. High revenue but low units means premium product.
A32: R5 — Sales Rep Ranking Table
A33: Task | B33: Pivot Table PT3 with Icon Sets applied. Top 3 highlighted green. Bottom 3 highlighted red.
A34: Answers | B34: Answers: Who needs coaching? Who deserves recognition?
A35: Note | B35: This is a sensitive table. Make sure the visual is clear but not unnecessarily harsh.
A37: R6 — Interactive Slicers
A38: Task | B38: Add slicers for Region, Category, and Month connected to all charts on the dashboard.
A39: Answers | B39: The CEO must be able to filter everything by clicking one button.
A40: Note | B40: This is what separates a static report from an interactive dashboard.
A42: HOW TO JUDGE YOUR OWN DASHBOARD
A43: Can the CEO understand the story in under 30 seconds without explanation?
A44: Does every chart answer a specific named business question?
A45: Are your KPI numbers accurate? Test them manually with SUMIF.
A46: Do the slicers actually control all charts or just one?
A47: Is the color usage intentional? Red for bad, green for good — consistently?
A48: Would you be comfortable presenting this in a real meeting?

Sheet Pivot tables
A3: Row Labels | B3: Sum of Revenue ($) | C3: Row Labels | D3: Sum of Revenue ($) | E3: Row Labels | F3: Sum of Revenue ($) | G3: Row Labels | H3: Sum of Revenue ($)
A4: East | B4: 38591 | C4: West | D4: 18563 | E4: Joshua Jackson | F4: 10997 | G4: Joshua Jackson | H4: 10997
A5: North | B5: 39435 | C5: South | D5: 18634 | E5: David Lee | F5: 20626 | G5: David Lee | H5: 20626
A6: South | B6: 18634 | C6: East | D6: 38591 | E6: James Wilson | F6: 21504 | G6: James Wilson | H6: 21504
A7: West | B7: 18563 | C7: North | D7: 39435 | E7: Grand Total | F7: 53127
A8: Grand Total | B8: 115223 | C8: Grand Total | D8: 115223
A10: Row Labels | B10: Sum of Revenue ($) | C10: Sum of Revenue ($) | D10: Column Labels
A11: January | B11: 42130 | C11: Row Labels | D11: Sports | E11: Electronics | F11: Home Appliances | G11: Clothing | H11: Beauty | I11: Grand Total
A12: February | B12: 21101 | C12: North | D12: 18294 | E12: 11490 | F12: 6240 | G12: 2634 | H12: 777 | I12: 39435
A13: March | B13: 18666 | C13: East | D13: 18654 | E13: 11290 | F13: 5400 | G13: 2452 | H13: 795 | I13: 38591
A14: April | B14: 7129 | C14: South | D14: 4980 | E14: 8140 | F14: 3840 | G14: 796 | H14: 878 | I14: 18634
A15: May | B15: 17230 | C15: West | D15: 5180 | E15: 8040 | F15: 3690 | G15: 812 | H15: 841 | I15: 18563
A16: June | B16: 8967 | C16: Grand Total | D16: 47108 | E16: 38960 | F16: 19170 | G16: 6694 | H16: 3291 | I16: 115223
A17: Grand Total | B17: 115223
A19: Sum of Revenue ($) | B19: Column Labels | F19: Row Labels | G19: Average of Revenue ($) | H19: Row Labels | I19: Average of Revenue ($)
A20: Row Labels | B20: Premium | C20: Standard | D20: Budget | E20: Grand Total | F20: West | G20: 371.26 | H20: Amanda Thomas | I20: 204.94118
A21: January | B21: 42130 | C21: 0 | D21: 0 | E21: 42130 | F21: South | G21: 372.68 | H21: Ashley White | I21: 255.125
A22: February | B22: 0 | C22: 21101 | D22: 0 | E22: 21101 | F22: East | G22: 771.82 | H22: Chris Anderson | I22: 544.05882
A23: March | B23: 0 | C23: 0 | D23: 18666 | E23: 18666 | F23: North | G23: 788.7 | H23: David Lee | I23: 1213.2941
A24: April | B24: 7129 | C24: 0 | D24: 0 | E24: 7129 | F24: Grand Total | G24: 576.115 | H24: Emily Davis | I24: 227.8125
A25: May | B25: 0 | C25: 17230 | D25: 0 | E25: 17230 | H25: James Wilson | I25: 1344
A26: June | B26: 0 | C26: 0 | D26: 8967 | E26: 8967 | H26: Jennifer Taylor | I26: 544.75
A27: Grand Total | B27: 49259 | C27: 38331 | D27: 27633 | E27: 115223 | H27: Joshua Jackson | I27: 646.88235
H28: Lisa Martinez | I28: 287.35294
A29: Row Labels | B29: Sum of Units Sold | C29: Sum of Revenue ($) | H29: Mike Johnson | I29: 553.94118
A30: Electronics | B30: 40 | C30: 38960 | H30: Robert Brown | I30: 594.35294
A31: Beauty | B31: 40 | C31: 3291 | H31: Sarah Connor | I31: 500.82353
A32: Home Appliances | B32: 60 | C32: 19170 | H32: Grand Total | I32: 576.115
A33: Clothing | B33: 60 | C33: 6694
A34: Sports | B34: 100 | C34: 47108
A35: Grand Total | B35: 300 | C35: 115223
A37: Row Labels | B37: Sum of Revenue ($)
A38: James Wilson | B38: 21504 | E38: 21504 | F38: Row Labels | G38: Sum of Revenue ($) | H38: =AVERAGE(G39:G44) -> 19203.833 | I38: 42130 | K38: =AVERAGE(I38:I43) -> 1196129.8
A39: North | B39: 21504 | E39: 20626 | F39: January | G39: 42130 | I39: 10988
A40: David Lee | B40: 20626 | E40: 10997 | F40: February | G40: 21101 | I40: 18666
A41: East | B41: 20626 | E41: 10104 | F41: March | G41: 18666 | I41: 7100000
A42: Joshua Jackson | B42: 10997 | E42: 9417 | F42: April | G42: 7129 | I42: 2652
A43: West | B43: 10997 | E43: 9249 | F43: May | G43: 17230 | I43: 2343
A44: Robert Brown | B44: 10104 | E44: 8716 | F44: June | G44: 8967
A45: South | B45: 10104 | E45: 8514 | F45: Grand Total | G45: 115223 | I45: Row Labels | J45: Sum of Revenue ($) | K45: =AVERAGE(J46:J75) -> 1712
...

Sheet AI Audit
A1: Week 4 — AI Audit Log
A2: Give each task to AI first. Record what it produced, what was wrong, and what you had to correct.
A4: AUDIT 1 — Ask AI to define KPIs for Nexacore. Compare its list to yours.
A5: Task given to AI
A6: Exact output AI produced
A7: Was AI correct? Yes / No / Partially
A8: What was wrong or missing
A9: Error type: KPI logic / Formula / Chart choice / Layout / Conceptual
A10: How you caught it
A11: What this reveals about AI limitations in business context
A13: AUDIT 2 — Ask AI to set up PT5 Region x Category pivot. Did it get the layout right?
A14: Task given to AI | B14: set up PT5 Region x Category pivot
A15: Exact output AI produced | B15: It used Sumif instead of pivot and changed the categories names also | F15: Region | G15: Electronics | H15: Apparel | I15: Home & Garden | J15: Sporting Goods | K15: Region Total
A16: Was AI correct? Yes / No / Partially | B16: No, it was completely wrong can lead any business to completely wrong direction. | F16: North | G16: 16815.64 | H16: 2582.19 | I16: 6496.66 | J16: 2463.51 | K16: 28358
A17: What was wrong or missing | B17: Formula reffrence, number's calculation, logical reasoning. | F17: South | G17: 20361.04 | H17: 2024.03 | I17: 2977.32 | J17: 2146.6 | K17: 27508.99
A18: Error type: KPI logic / Formula / Chart choice / Layout / Conceptual | B18: Formula, Conceptual. | F18: East | G18: 20488.95 | H18: 3630.25 | I18: 4744.96 | J18: 804.63 | K18: 29668.79
A19: How you caught it | B19: Comparing to my pivot table. | F19: West | G19: 16025.85 | H19: 2676.55 | I19: 6888.62 | J19: 1785.12 | K19: 27376.14
A20: What this reveals about AI limitations in business context | B20: When data is a bit large it gets confused with reffrences and logics could be the reason that it has to manage command logic, task logic, calculating every single logic then handling task logic and calculating task data gets complicated for it to solve specially when data given is large. | F20: Category Total | G20: 73691.48 | H20: 10913.02 | I20: 21107.56 | J20: 7199.86 | K20: 112911.92
A22: AUDIT 3 — Ask AI to write formulas for the KPI Summary Row in the dashboard.
A23: Task given to AI | B23: write formulas for the KPI Summary Row in the dashboard.
A24: Exact output AI produced | B24: it used =SUM('Sales Data'!$I$2:$I$253) for total revenue and =SUM('Sales Data'!$H$2:$H$253) for Total units sold and =INDEX('PT1 Revenue by Region'!$A$6:$A$9,MATCH(MAX('PT1 Revenue by Region'!$B$6:$B$9),'PT1 Revenue by Region'!$B$6:$B$9,0)) for Top region and =INDEX('PT3 Revenue by Sales Rep'!$A$6:$A$13,MATCH(MAX('PT3 Revenue by Sales Rep'!$B$6:$B$13),'PT3 Revenue by Sales Rep'!$B$6:$B$13,0)) for top sales rep | F24: TOTAL REVENUE | J24: TOTAL UNITS SOLD | N24: TOP REGION | R24: TOP SALES REP
A25: Was AI correct? Yes / No / Partially | B25: No | F25: 112911.92 | J25: 933 | N25: East | R25: Sarah Chen
A26: What was wrong or missing | B26: formula reffrence was completely wrong.
A27: Error type: KPI logic / Formula / Chart choice / Layout / Conceptual | B27: Formula
A28: How you caught it | B28: check formula's reffrence it was completely wrong and then compare it to my answer
A29: What this reveals about AI limitations in business context | B29: again When data is a bit large it gets confused with reffrences and logics could be the reason that it has to manage command logic, task logic, calculating every single logic then handling task logic and calculating task data gets complicated for it to solve specially when data given is large.
A31: AUDIT 4 — Ask AI which chart types to use for each Pivot Table. Does it justify its choices?
A32: Task given to AI | B32: which chart types to use for each Pivot Table.
A33: Exact output AI produced | B33: it used column for comparing charts instead of bar chart else it chose write charts
A34: Was AI correct? Yes / No / Partially | B34: partially
A35: What was wrong or missing | B35: logical reasoning 2nd person perspective
A36: Error type: KPI logic / Formula / Chart choice / Layout / Conceptual | B36: chart choice
A37: How you caught it | B37: comparing chart data and chart type
A38: What this reveals about AI limitations in business context | B38: it reveales that AI just finishes task it doesn't care about who this will be present to will the next person be able to understand it or will the person get the point data tells inshort AI lacks storytelling in data analysis and data visualization.
A40: AUDIT 5 — Ask AI to design the dashboard layout. Does it account for the CEO's perspective?
A41: Task given to AI | B41: AI to design the dashboard layout
A42: Exact output AI produced | B42: it placed four KPI summeries in first row total revenue, total units sold, top region, top sales rep in four boxes with solid colour then it placed two tables below one of top three sales rep second of bottom three sales rep which are also wrong then it placed three charts under that revenue by region, revenue by category, monthly revenue trend which is also wrong the monthly revenue trend has massive calculation mistakes completely misrepresentating the montly revenue trend the charts width is not same no colour theory no structure we need to scroll down to see the charts.
A43: Was AI correct? Yes / No / Partially | B43: No
A44: What was wrong or missing | B44: dashboard layout was absolutely wrong I wouldn't say not a single one but the rules that matters the most in dashboard designing wasn't applied even the basic one.
A45: Error type: KPI logic / Formula / Chart choice / Layout / Conceptual | B45: layout, conceptual
...
